Workbook

Sheet 说明
A1: 说明：
A2: 1 | B2: 本计算输入数据来自杜邦工艺包及Htri5.0的计算结果：
B3: 1.1 | C3: 表Streams中的数据为Aspen Plus计算结果的物流数据表。
B4: 1.2 | C4: 表TraySizingT-101、TraySizingT-103为Aspen Plus进行的塔板塔径等计算数据，可供确定塔径用。
B5: 1.3 | C5: 表HydraulicsT-101、HydraulicsT-103为Aspen Plus塔的水力学计算数据，可供塔内件厂家选型计算用。
A7: 2 | B7: 文字颜色意义定义：
B8: 输入文字及数据
B9: 链接文字及数据
B10: 公式计算数据
B11: 提示注意数据
B12: 判断文字或数据 | D12: 通过 | E12: 警告 | F12: 未通过

Sheet 作业流程
A1: 工艺专业作业流程——惠州二期340万吨/年柴油加氢装置
A2: 表头 | B2: 项目信息 | C2: 输入
A3: 序列 | B3: 主流程项 | C3: 进度 | D3: 外部专业条件1 | E3: 进度 | F3: 外部专业条件2 | G3: 进度 | H3: 外部专业条件3 | I3: 进度 | J3: 外部专业条件4 | K3: 进度 | L3: 外部专业条件5 | M3: 进度 | N3: 开始时间 | O3: 完成时间
A4: =ROW()-2 -> 2 | B4: 整理基础设计资料 | C4: 完成 | N4: 41771 | O4: =N4+2 -> 41773
A5: =ROW()-2 -> 3 | B5: PFD图 | C5: 完成 | N5: =N4 -> 41771 | O5: =N17-1 -> 41817
A6: =ROW()-2 -> 4 | B6: 流程模拟 | C6: 不需要 | D6: 下游装置物料条件发下游装置工艺专业 | E6: 未开始 | N6: =N5 -> 41771 | O6: =N6+30 -> 41801
A7: =ROW()-2 -> 5 | B7: 换热网络设计 | C7: 进行中 | D7: 燃料消耗、化学药剂消耗发项目工程师、安全环保专业 | E7: 不需要 | F7: 加热炉条件发工业炉专业 | G7: 未开始 | H7: 分析化验项目条件发项目工程师、管道专业 | I7: 未开始 | N7: =O6+1 -> 41802 | O7: =N7+15 -> 41817
A8: =ROW()-2 -> 6 | B8: 反应器计算 | C8: 不需要 | D8: 反应器数据表共享给设备、自控、管道专业编辑 | E8: 未开始 | F8: 反应器汇总表共享给设备专业编辑 | G8: 未开始 | H8: 反应器数据表订货资料发项目工程师 | I8: 未开始 | J8: 污染物的排放（处理）资料提项目工程师 | K8: 未开始 | N8: =O6+1 -> 41802 | O8: =N8+45 -> 41847
A9: =ROW()-2 -> 7 | B9: 塔径计算 | C9: 不需要 | D9: 塔数据表共享给设备、自控、管道专业编辑 | E9: 未开始 | F9: 塔汇总表共享给设备专业编辑 | G9: 未开始 | H9: 塔数据表订货资料发项目工程师 | I9: 未开始 | N9: =N8 -> 41802 | O9: =N9+45 -> 41847
A10: =ROW()-2 -> 8 | B10: 换热器计算 | C10: 进行中 | D10: 换热器数据表共享给设备、管道专业编辑 | E10: 未开始 | F10: 换热器汇总表共享给设备专业编辑 | G10: 未开始 | H10: 换热器数据表订货资料发项目工程师 | I10: 未开始 | J10: 给排水设计条件发给排水专业 | K10: 未开始 | L10: 公用工程（含氢气、氮气）消耗给项目工程师 | M10: 未开始 | N10: =O7+1 -> 41818 | O10: =N10+30 -> 41848
A11: =ROW()-2 -> 9 | B11: 空冷计算 | C11: 进行中 | D11: 空冷器数据表共享给设备、管道、电气专业编辑 | E11: 未开始 | F11: 空冷器汇总表共享给设备、电气专业编辑 | G11: 未开始 | H11: 空冷器数据表订货资料发项目工程师 | I11: 未开始 | N11: =N10 -> 41818 | O11: =N11+30 -> 41848
A12: =ROW()-2 -> 10 | B12: 容器选型 | C12: 完成 | D12: 容器数据表共享给设备、自控、管道专业编辑 | E12: 未开始 | F12: 容器汇总表共享给设备、管道专业编辑 | G12: 未开始 | H12: 容器数据表订货资料发项目工程师 | I12: 未开始 | J12: 设备基础条件发管道 | K12: 未开始 | N12: =N11 -> 41818 | O12: =N12+30 -> 41848
A13: =ROW()-2 -> 11 | B13: 安全阀选型 | C13: 未开始 | D13: 安全阀数据表共享给管道专业编辑 | E13: 未开始 | F13: 安全阀汇总表共享给管道专业编辑 | G13: 未开始 | H13: 安全阀数据表订货资料发项目工程师 | I13: 未开始 | N13: =N12 -> 41818 | O13: =N13+30 -> 41848
A14: =ROW()-2 -> 12 | B14: 管径核算 | C14: 进行中 | D14: 管道表共享给管道专业编辑 | E14: 未开始 | F14: 界区条件表共享给管道专业编辑 | G14: 未开始 | H14: 界区条件表发项目工程师 | I14: 未开始 | N14: =N13 -> 41818 | O14: =N14+30 -> 41848
A15: =ROW()-2 -> 13 | B15: 机泵、压缩机选型 | C15: 未开始 | D15: 泵、压缩机数据表共享给电气、管道、机械专业编辑 | E15: 未开始 | F15: 电专业条件发电气专业 | G15: 未开始 | N15: =N14 -> 41818 | O15: =N15+30 -> 41848
A16: =ROW()-2 -> 14 | B16: 过滤器、喷射器选型 | C16: 未开始 | D16: 过滤器、喷射器数据表共享给管道、自控专业编辑 | E16: 未开始 | N16: =O15+1 -> 41849 | O16: =N16+15 -> 41864
A17: =ROW()-2 -> 15 | B17: P&ID图 | C17: 进行中 | D17: P&ID图共享给管道、自控专业编辑 | E17: 未开始 | F17: “图例符号说明”共享给自控签字 | G17: 未开始 | H17: 自控专业条件发自控专业 | I17: 未开始 | J17: 盲板、限流或降压孔板设计条件发管道专业 | K17: 未开始 | N17: =O7+1 -> 41818 | O17: =N17+31 -> 41849
A18: =ROW()-2 -> 16 | B18: 说明书 | C18: 未开始 | N18: =O17+1 -> 41850 | O18: =N18+15 -> 41865
A19: =ROW()-2 -> 17 | B19: 目录 | C19: 未开始 | N19: =O18+1 -> 41866 | O19: =N19+15 -> 41881
A20: =ROW()-2 -> 18 | B20: 签字检查 | C20: 未开始 | N20: =O19+1 -> 41882 | O20: =N20+1 -> 41883
A22: 注： | B22: 以本专业主流程为Y轴，以外专业条件为X轴。每完成一个Y轴主流程后，就要完成X轴上的所有任务：主流程项1--〉外部专业条件1--〉外部专业条件2-->外部专业条件X……-->主流程项2-->……

Sheet 项目信息
A1: 公称规模，万吨/年 | B1: 260
A2: 操作弹性 | B2: =输入!D3 -> 60~110
A3: 年工作时数，h | B3: 8400
A5: 基本风压 | B5: 714 | C5: Pa
A6: 抗震设防烈度 | B6: 7 度Grade | C6: 7
A7: 地面粗糙度类别 | B7: A类 Category A | C7: 合同技术附件中没有定
A8: 场地土类别 | B8: Ⅲ类 ClassⅢ
A9: 设计地震分组 | B9: 第二组 Number 2
A10: 基本加速度 | B10: 0.10g
A11: 最高气温，℃ | B11: 38.9
A12: 最低气温，℃ | B12: 0.5
A13: 年平均气压，Kpa | B13: 101.07
A14: 海拔高度，m | B14: 350
A15: 非净化压缩空气压力，MPaG | B15: 0.5
A16: 非净化压缩空气温度，℃ | B16: 常温
A17: 净化压缩空气压力，MPaG | B17: 0.5
A18: 净化压缩空气温度，℃ | B18: 常温
A19: 氮气压力，MPaG | B19: 0.6
A20: 氮气温度，℃ | B20: 40
A21: 新鲜水压力，MPaG | B21: 0.35
A22: 新鲜水温度，℃ | B22: 常温
A23: 循环水给水压力，MPaG | B23: 0.4
A24: 循环水给水温度，℃ | B24: 33
A25: 循环水回水压力，MPaG | B25: 0.2
A26: 循环水回水温度，℃ | B26: 43
A27: 低温热水给水压力，MPaG | B27: 0.8
A28: 低温热水给水温度，℃ | B28: 105
A29: 低温热水回水压力，MPaG | B29: 0.5
A30: 低温热水回水温度，℃ | B30: 65
A31: 冷凝水压力，MPaG | B31: 0.8
A32: 冷凝水温度，℃ | B32: 175
A33: 中压蒸汽压力，MPaG | B33: 3.5
A34: 中压蒸汽温度，℃ | B34: 440
... A38: 中压电，v | B38: 10000
A39: 低压电，v | B39: 380 | C39: 220
A40: 频率，HZ | B40: 50±0.5
A41: 空气湿度（最大）,% | B41: 71
A42: 空气湿度（最小）,% | B42: 45
A43: 空气湿度（年平均）,% | B43: 53
A44: 年平均降雨量，mm | B44: 1729
...

Sheet 输入
B1: 惠州柴油加氢
A2: 1 | B2: 装置规模 | C2: 万吨/年 | D2: 340
A3: 2 | B3: 操作弹性 | C3: % | D3: 60~110
A4: 3 | B4: 年开工时数 | C4: 小时 | D4: 8400
A5: 4 | B5: 生产方案 | C5: 混合芳烃 | D5: 低硫中芳烃 | E5: 蜡油 | F5: 减压尾油 | G5: 兼产液化气
A6: 5 | B6: 物料平衡 | G6: 按氢耗3%(相对于新鲜原料)修订:
C7: wt% | D7: kg/h | E7: 万吨/年 | H7: wt% | I7: kg/h | J7: 万吨/年
B8: 进料 | G8: 进料
B9: 委内瑞拉玛瑞燃料油 | C9: =#REF! -> #REF! | D9: =#REF! -> #REF! | E9: =D9*0.8/1000 -> #REF! | G9: 委内瑞拉玛瑞燃料油 | H9: =#REF! -> #REF! | I9: =#REF! -> #REF! | J9: =I9*0.8/1000 -> #REF!
B10: 催化剂与助剂 | C10: =#REF! -> #REF! | D10: =#REF! -> #REF! | E10: =D10*0.8/1000 -> #REF! | G10: 催化剂与助剂 | H10: =#REF! -> #REF! | I10: =#REF! -> #REF! | J10: =I10*0.8/1000 -> #REF!
B11: 耗氢量 | C11: =#REF! -> #REF! | D11: =#REF! -> #REF! | E11: =D11*0.8/1000 -> #REF! | G11: 耗氢量 | H11: =#REF! -> #REF! | I11: =#REF! -> #REF! | J11: =I11*0.8/1000 -> #REF!
B12: 合计 | C12: =#REF! -> #REF! | D12: =#REF! -> #REF! | E12: =D12*0.8/1000 -> #REF! | G12: 合计 | H12: =#REF! -> #REF! | I12: =#REF! -> #REF! | J12: =I12*0.8/1000 -> #REF!
B13: 出料 | G13: 出料
B14: NH3 | C14: =D14/$D$22*100 -> #REF! | D14: =#REF! -> #REF! | E14: =D14*0.8/1000 -> #REF! | G14: NH3 | H14: =#REF! -> #REF! | I14: =#REF! -> #REF! | J14: =I14*0.8/1000 -> #REF!
B15: H2S | C15: =D15/$D$22*100 -> #REF! | D15: =#REF! -> #REF! | E15: =D15*0.8/1000 -> #REF! | G15: H2S | H15: =#REF! -> #REF! | I15: =#REF! -> #REF! | J15: =I15*0.8/1000 -> #REF!
B16: 干气 | C16: =D16/$D$22*100 -> #REF! | D16: =#REF! -> #REF! | E16: =D16*0.8/1000 -> #REF! | G16: 干气 | H16: =#REF! -> #REF! | I16: =#REF! -> #REF! | J16: =I16*0.8/1000 -> #REF!
B17: 液化气 | C17: =D17/$D$22*100 -> #REF! | D17: =#REF! -> #REF! | E17: =D17*0.8/1000 -> #REF! | G17: 液化气 | H17: =#REF! -> #REF! | I17: =#REF! -> #REF! | J17: =I17*0.8/1000 -> #REF!
B18: 混合芳烃（C5～180℃） | C18: =D18/$D$22*100 -> #REF! | D18: =#REF! -> #REF! | E18: =D18*0.8/1000 -> #REF! | G18: 混合芳烃（C5～180℃） | H18: =#REF! -> #REF! | I18: =#REF! -> #REF! | J18: =I18*0.8/1000 -> #REF!
B19: 低硫中芳烃（180～360℃） | C19: =D19/$D$22*100 -> #REF! | D19: =#REF! -> #REF! | E19: =D19*0.8/1000 -> #REF! | G19: 低硫中芳烃（180～360℃） | H19: =#REF! -> #REF! | I19: =#REF! -> #REF! | J19: =I19*0.8/1000 -> #REF!
B20: 蜡油（360～540℃） | C20: =D20/$D$22*100 -> #REF! | D20: =#REF! -> #REF! | E20: =D20*0.8/1000 -> #REF! | G20: 蜡油（360～540℃） | H20: =#REF! -> #REF! | I20: =#REF! -> #REF! | J20: =I20*0.8/1000 -> #REF!
B21: 减压尾油（>540℃） | C21: =D21/$D$22*100 -> #REF! | D21: =#REF! -> #REF! | E21: =D21*0.8/1000 -> #REF! | G21: 减压尾油（>540℃） | H21: =#REF! -> #REF! | I21: =#REF! -> #REF! | J21: =I21*0.8/1000 -> #REF!
B22: 合计 | C22: =SUM(C14:C21) -> #REF! | D22: =D12 -> #REF! | E22: =D22*0.8/1000 -> #REF! | G22: 合计 | H22: =#REF! -> #REF! | I22: =#REF! -> #REF! | J22: =I22*0.8/1000 -> #REF!
A24: 6 | B24: 反应器型式
B25: 临氢热裂解反应器 | C25: 浆液床
B26: 后加氢精制反应器 | C26: 滴流床
A28: 7 | B28: 主要操作条件
B29: 反应器名称 | C29: 出口总压MPaG | D29: 体积空速/hr | E29: 温度℃ | F29: 氢油比，Nm3/m3
B31: 加氢裂解反应器入口 | C31: =C32 -> 13.25 | D31: 1 | E31: 440 | F31: 800
B32: 加氢裂解反应器出口 | C32: =F51+0.3 -> 13.25 | E32: 440
B33: 加氢精制反应器入口 | C33: =C34+0.3 -> 12.9 | D33: 1 | E33: 360 | F33: 800
B34: 加氢精制反应器出口 | C34: =F54+0.4 -> 12.6 | E34: 370
D35: 原来 | F35: 调整后 | H35: 惠州高压蜡油加氢循环氢压缩机入口、出口压降
B36: 新氢压缩机入口压力 | C36: MPaG | D36: 2 | F36: =D36 -> 2 | H36: sor | I36: eor
B37: 新氢压缩机出口压力 | C37: MPaG | D37: 11 | E37: 1.5MPG系统压降 | F37: =C31+0.5+0.3 -> 14.05 | H37: 13.86 | I37: 13.92 | J37: =I37-H37 -> 0.06
B38: 循环氢压缩机入口压力 | C38: MPaG | D38: 11 | F38: =F49-0.1 -> 11.8 | G38: 2.25MPa系统压降 | H38: 15.89 | I38: 16.35 | J38: =I38-H38 -> 0.46
B39: 循环氢压缩机出口压力 | C39: MPaG | D39: 12.5 | F39: =F37 -> 14.05 | H39: =H38-H37 -> 2.03 | I39: =I38-I37 -> 2.43
B40: 低硫中芳烃汽提塔顶压力 | C40: MPaG
B41: 减压塔顶压力 | C41: kPaA | D41: 2 | F41: 2
B42: 硫化氢汽提塔顶压力 | C42: MPaG | D42: 0.9 | F42: 0.9
B43: 汽提蒸汽压力 | C43: MPaG | D43: 1 | F43: 1
...

Sheet 柴油加氢物料平衡(杜邦)
G1: 处理能力： | H1: 260 | I1: 万吨/年
G2: 操作时数 | H2: 8400 | I2: 小时/年
B3: 加氢装置物料平衡 | F3: 总物料平衡（按氢耗3w%调整） | M3: 产品硫分布计算 | Q3: 产品氮分布计算
B4: 进料 | C4: 进出料名称 | D4: 百分率，wt% | F4: 进料 | G4: 进出料名称 | H4: 百分率，wt% | I4: 数量 | J4: 单位 | K4: 万吨/年 | M4: 项目 | N4: 数值 | O4: 备注 | Q4: 项目 | R4: 数值 | S4: 备注
C5: 委内瑞拉玛瑞燃料油 | D5: 97.8 | G5: 委内瑞拉玛瑞燃料油 | H5: =I5/$I$8*100 -> #REF! | I5: =H1/H2*10000*1000 -> 309523.81 | J5: kg/h | K5: =I5*$H$2/1000/10000 -> 260 | M5: 原料油硫含量（m,%) | N5: 2.84 | O5: 见本次“设计基础数据”表1 | Q5: 原料油氮含量（m,%) | R5: 0.5 | S5: 见“设计基础数据”表1
C6: 催化剂与助剂 | D6: 0.3 | G6: 催化剂与助剂 | H6: =I6/$I$8*100 -> #REF! | I6: =#REF! -> #REF! | J6: kg/h | K6: =I6*$H$2/1000/10000 -> #REF! | M6: 原料油硫占总进料（m,%) | N6: =N5*H5/100 -> #REF! | Q6: 原料油氮占总进料（m,%) | R6: =R5*H5/100 -> #REF!
C7: 耗氢量 | D7: 1.9 | G7: 耗氢量 | H7: =I7/$I$8*100 -> #REF! | I7: 3750 | J7: kg/h | K7: =I7*$H$2/1000/10000 -> 3.15 | M7: 减压尾油硫含量(m,%) | N7: 3.89 | O7: 见本次“设计基础数据”表16 | Q7: 减压尾油氮含量(m,%) | R7: 1.53 | S7: 见“设计基础数据”表16
C8: 总进料 | D8: 100 | G8: 总进料 | H8: =SUM(H5:H7) -> #REF! | I8: =SUM(I5:I7) -> #REF! | J8: kg/h | K8: =I8*$H$2/1000/10000 -> #REF! | M8: 减压尾油硫占总出料含量(m,%) | N8: =N7*H16/100 -> #REF! | O8: 尾油未精制 | Q8: 减压尾油氮占总出料含量(m,%) | R8: =R7*H16/100 -> #REF! | S8: 尾油未精制
B9: 出料 | C9: NH3 | D9: 0.03 | F9: 出料 | G9: NH3 | H9: =I9/$I$17*100 -> #REF! | I9: =#REF! -> #REF! | J9: kg/h | K9: =I9*$H$2/1000/10000 -> #REF! | M9: 液化气中硫含量(m,ppm) | N9: 20 | Q9: 液化气中氮含量(m,ppm) | R9: 0
C10: H2S | D10: 1.1 | G10: H2S | H10: =I10/$I$17*100 -> #REF! | I10: =#REF! -> #REF! | J10: kg/h | K10: =I10*$H$2/1000/10000 -> #REF! | M10: 液化气中硫占总出料含量(m,%) | N10: =N9/1000000*H12 -> #REF! | Q10: 液化气中氮占总出料含量(m,%) | R10: =R9/1000000*H12 -> #REF!
C11: 干气 | D11: 1.74 | G11: 干气 | H11: =I11/$I$17*100 -> #REF! | I11: =#REF!+I7-#REF! -> #REF! | J11: kg/h | K11: =I11*$H$2/1000/10000 -> #REF! | M11: 石脑油中硫含量(m,%) | N11: 0.005 | O11: 380#精制后实验数据，GB17920-2011为0.015 | Q11: 石脑油中氮含量(m,%) | R11: 0.0017 | S11: 380#精制后实验数据
C12: 液化气 | D12: 1.74 | G12: 液化气 | H12: =I12/$I$17*100 -> #REF! | I12: =#REF! -> #REF! | J12: kg/h | K12: =I12*$H$2/1000/10000 -> #REF! | M12: 石脑油中硫占总出料含量(m,%) | N12: =N11*H13/100 -> #REF! | Q12: 石脑油中氮占总出料含量(m,%) | R12: =R11*H13/100 -> #REF!
C13: 石脑油（C5～180℃） | D13: 11.54 | G13: 石脑油（C5～180℃） | H13: =I13/$I$17*100 -> #REF! | I13: =#REF! -> #REF! | J13: kg/h | K13: =I13*$H$2/1000/10000 -> #REF! | M13: 柴油中硫含量(m,%) | N13: 0.004 | O13: 380#精制后实验数据，GB19147-2009为0.035 | Q13: 柴油中氮含量(m,%) | R13: 0.0019 | S13: 380#精制后实验数据
C14: 柴油馏分（180～360℃） | D14: 43.28 | G14: 柴油馏分（180～360℃） | H14: =I14/$I$17*100 -> #REF! | I14: =#REF! -> #REF! | J14: kg/h | K14: =I14*$H$2/1000/10000 -> #REF! | M14: 柴油中硫占总出料含量(m,%) | N14: =N13*H14/100 -> #REF! | Q14: 柴油中氮占总出料含量(m,%) | R14: =R13*H14/100 -> #REF!
C15: 蜡油（360～540℃） | D15: 26.53 | G15: 蜡油（360～540℃） | H15: =I15/$I$17*100 -> #REF! | I15: =#REF! -> #REF! | J15: kg/h | K15: =I15*$H$2/1000/10000 -> #REF! | M15: 蜡油中硫含量(m,%) | N15: 0.023 | O15: 380#精制后实验数据 | Q15: 蜡油中氮含量(m,%) | R15: 0.0053 | S15: 380#精制后实验数据
C16: 减压尾油（>540℃） | D16: 14.04 | G16: 减压尾油（>540℃） | H16: =I16/$I$17*100 -> #REF! | I16: =#REF! -> #REF! | J16: kg/h | K16: =I16*$H$2/1000/10000 -> #REF! | M16: 蜡油中硫占总出料含量(m,%) | N16: =N15*H15/100 -> #REF! | Q16: 蜡油中氮占总出料含量(m,%) | R16: =R15*H15/100 -> #REF!
C17: 合计 | D17: 100 | G17: 合计 | H17: =SUM(H9:H16) -> #REF! | I17: =SUM(I9:I16) -> #REF! | J17: kg/h | K17: =I17*$H$2/1000/10000 -> #REF! | M17: H2S中硫占总出料含量(m,%) | N17: =N6-N8-N10-N12-N14-N16 -> #REF! | Q17: NH3中氮占总出料含量(m,%) | R17: =R6-R8-R10-R12-R14-R16 -> #REF!
C18: 甲苯不溶物 | D18: 0.31 | M18: H2S占总出料含量(m,%) | N18: =N17*34/32 -> #REF! | Q18: NH3占总出料含量(m,%) | R18: =R17*17/14 -> #REF!
B19: 注：本表数据由石油大学提供 | F19: 注：按精制后仅蜡油减少计算产品分布
F22: 修改后物料平衡
F24: 进料 | G24: 进出料名称 | H24: 百分率，wt% | I24: 数量 | J24: 单位 | L24: S% | M24: S，kg/h | N24: 分布，% | P24: N% | Q24: N，kg/h | R24: 分布，%
G25: 委内瑞拉玛瑞燃料油 | H25: =I25/1293.75 -> 96.618357 | I25: 125000 | J25: kg/h | L25: 2.84 | M25: =L25*I25/100 -> 3550 | N25: =M25/35.5 -> 100 | P25: 0.5 | Q25: =P25*I25/100 -> 625 | R25: =Q25/6.25 -> 100
G26: 催化剂与助剂 | H26: =I26/1293.75 -> 0.48309179 | I26: 625 | J26: kg/h | R26: =Q26/6.25 -> 0
G27: 耗氢量 | H27: =I27/1293.75 -> 2.8985507 | I27: 3750 | J27: kg/h | R27: =Q27/6.25 -> 0
G28: 总进料 | H28: =SUM(H25:H27) -> 100 | I28: =SUM(I25:I27) -> 129375 | J28: kg/h | M28: 3550 | N28: =M28/35.5 -> 100 | Q28: 625 | R28: =Q28/6.25 -> 100
F29: 出料 | G29: NH3 | H29: =I29/$I$37*100 -> 0.28224155 | I29: 365.15 | J29: kg/h | M29: =L29*I29/100 -> 0 | N29: =M29/35.5 -> 0 | P29: 82.35 | Q29: =P29*I29/100 -> 300.70103 | R29: =Q29/6.25 -> 48.112164
G30: H2S | H30: =I30/$I$37*100 -> 2.2360193 | I30: 2892.85 | J30: kg/h | L30: 94.12 | M30: =L30*I30/100 -> 2722.7504 | N30: =M30/35.5 -> 76.697195 | Q30: =P30*I30/100 -> 0 | R30: =Q30/6.25 -> 0
G31: 干气 | H31: =I31/$I$37*100 -> 2.0228019 | I31: 2617 | J31: kg/h | M31: =L31*I31/100 -> 0 | N31: =M31/35.5 -> 0 | Q31: =P31*I31/100 -> 0 | R31: =Q31/6.25 -> 0
G32: 液化气 | H32: =I32/$I$37*100 -> 1.7391304 | I32: 2250 | J32: kg/h | L32: 0.002 | M32: =L32*I32/100 -> 0.045 | N32: =M32/35.5 -> 0.0012676056 | Q32: =P32*I32/100 -> 0 | R32: =Q32/6.25 -> 0
G33: 石脑油（C5～180℃） | H33: =I33/$I$37*100 -> 10.743961 | I33: 13900 | J33: kg/h | L33: 0.005 | M33: =L33*I33/100 -> 0.695 | N33: =M33/35.5 -> 0.019577465 | P33: 0.0017 | Q33: =P33*I33/100 -> 0.2363 | R33: =Q33/6.25 -> 0.037808
G34: 柴油馏分（180～360℃） | H34: =I34/$I$37*100 -> 41.73913 | I34: 54000 | J34: kg/h | L34: 0.004 | M34: =L34*I34/100 -> 2.16 | N34: =M34/35.5 -> 0.06084507 | P34: 0.0019 | Q34: =P34*I34/100 -> 1.026 | R34: =Q34/6.25 -> 0.16416
G35: 蜡油（360～540℃） | H35: =I35/$I$37*100 -> 25.004831 | I35: 32350 | J35: kg/h | L35: 0.023 | M35: =L35*I35/100 -> 7.4405 | N35: =M35/35.5 -> 0.20959155 | P35: 0.0053 | Q35: =P35*I35/100 -> 1.71455 | R35: =Q35/6.25 -> 0.274328
G36: 减压尾油（>540℃） | H36: =I36/$I$37*100 -> 16.231884 | I36: 21000 | J36: kg/h | L36: 3.89 | M36: =L36*I36/100 -> 816.9 | N36: =M36/35.5 -> 23.011268 | P36: 1.53 | Q36: =P36*I36/100 -> 321.3 | R36: =Q36/6.25 -> 51.408
G37: 合计 | H37: =SUM(H29:H36) -> 100 | I37: =SUM(I29:I36) -> 129375 | J37: kg/h | M37: =SUM(M30:M36) -> 3549.9909 | N37: =M37/35.5 -> 99.999744 | Q37: =SUM(Q29:Q36) -> 624.97788 | R37: =Q37/6.25 -> 99.99646

Sheet 物流参数
B1: Unit | C1: 100 | D1: 101 | E1: 102 | F1: 103 | G1: 104 | H1: 105 | I1: 106 | J1: 107 | K1: 108 | L1: 109 | M1: 110 | N1: 111 | O1: 112 | P1: 113 | Q1: 114 | R1: 115 | S1: 116 | T1: 117 | U1: 118 | V1: 119 | W1: 120 | X1: 121 | Y1: 200 | Z1: 201 | AA1: 202 | AB1: 203 | AC1: 204 | AD1: 205 | AE1: 206 | AF1: 207 | AG1: 208 | AH1: 209 | AI1: 210 | AJ1: 211 | AK1: 212 | AL1: 213 | AM1: 214 | AN1: 215 | AO1: 216 | AP1: 217 | AQ1: 218 | AR1: 219 | AS1: 220 | AT1: 221 | AU1: 222 | AV1: 223 | AW1: 224 | AX1: 225 | AY1: 300 | AZ1: 301 | BA1: 302 | BB1: 303 | BC1: 304 | BD1: 305 | BE1: 306 | BF1: 307 | BG1: 308 | BH1: 309 | BI1: 310 | BJ1: 311 | BK1: 312 | BL1: 313 | BM1: 314 | BN1: 315 | BO1: 316 | BP1: 317 | BQ1: 318 | BR1: 319 | BS1: 320 | BT1: 321 | BU1: 322 | BV1: 400 | BW1: 401 | BX1: 402 | BY1: 403 | BZ1: 404 | CA1: 405 | CB1: 406 | CC1: 407 | CD1: 408 | CE1: 409 | CF1: 410 | CG1: 411 | CH1: 412 | CI1: 413 | CJ1: 414 | CK1: 415 | CL1: 416 | CM1: 417 | CN1: 418 | CO1: 419 | CP1: 420 | CQ1: 421 | CR1: 422 | CS1: 423 | CT1: 424 | CU1: 425 | CV1: 426 | CW1: 427 | CX1: 428 | CY1: 429 | CZ1: 500 | DA1: 501 | DB1: 502 | DC1: 503 | DD1: 504 | DE1: 505 | DF1: 506 | DG1: 507 | DH1: 508 | DI1: 509 | DJ1: 510 | DK1: 511 | DL1: 512 | DM1: 513 | DN1: 514 | DO1: 515 | DP1: 516 | DQ1: 517 | DR1: 518 | DS1: 519 | DT1: 520 | DU1: 521 | DV1: 522 | DW1: 523 | DX1: 524 | DY1: 525 | DZ1: 526 | EA1: 527 | EB1: 528 | EC1: 529 | ED1: 530 | EE1: 531 | EF1: 532 | EG1: 533 | EH1: 600 | EI1: 601 | EJ1: 602 | EK1: 603 | EL1: 604 | EM1: 605 | EN1: 606 | EO1: 607 | EP1: 608 | EQ1: 609 | ER1: 610 | ES1: 611 | ET1: 612 | EU1: 613 | EV1: 614 | EW1: 700 | EX1: 701 | EY1: 702 | EZ1: 703 | FA1: 704 | FB1: 705 | FC1: 706 | FD1: 707 | FE1: 708 | FF1: 709 | FG1: 710 | FH1: 711 | FI1: 712
A3: TOTAL MASS FLOW | B3: kg/h | C3: 26676.4 | D3: 236419 | E3: 46428.6 | F3: 263095.4 | G3: 46428.6 | H3: 309524 | I3: 309524 | J3: 309524 | K3: 309524 | L3: 309524 | M3: 309524 | N3: 446 | O3: 309970 | P3: 268934.3 | Q3: 309970 | R3: 268934.3 | S3: 40340.14 | T3: 40340.14 | U3: 40340.14 | V3: 228594.15 | W3: 309524 | X3: 309524 | Y3: 309970 | Z3: 309970 | AA3: 741526.97 | AB3: 428894.98 | AC3: 428894.98 | AD3: 738864.98 | AE3: 739147.94 | AF3: 282.96 | AG3: 605.14 | AH3: 736.13 | AI3: 667.64 | AJ3: 479.56 | AK3: 16.66 | AL3: 19.15 | AM3: 19.15 | AN3: 24.85 | AO3: 26.92 | AP3: 109.44 | AQ3: 312631.98 | AR3: 312631.98 | AS3: 312631.98 | AT3: 312631.98 | AU3: 6702.76 | AV3: 5215.35 | AW3: 5238.27 | AX3: 22.9 | AY3: 12588.46 | AZ3: 12697.9 | BA3: 12697.9 | BB3: 23397.9 | BC3: 23397.9 | BD3: 27715.9 | BE3: 27715.9 | BF3: 11306.67 | BG3: 16068.71 | BH3: 4604.55 | BI3: 4604.55 | BJ3: 11804.68 | BK3: 11804.68 | BL3: 300043.52 | BM3: 300043.52 | BN3: 32429.87 | BO3: 3189.14 | BP3: 13100 | BQ3: 13100 | BR3: 13100 | BS3: 2400 | BT3: 10700 | BU3: 4318 | BV3: 6542.55 | BW3: 300816.72 | BX3: 300816.72 | BY3: 300816.72 | BZ3: 300816.72 | CA3: 7799.01 | CB3: 7799.01 | CC3: 293017.71 | CD3: 293017.71 | CE3: 293017.71 | CF3: 268934.3 | CG3: 312631.98 | CH3: 20673.98 | CI3: 23073.98 | CJ3: 23073.98 | CK3: 23073.98 | CL3: 15182.02 | CM3: 15182.02 | CN3: 7350.08 | CO3: 7831.94 | CP3: 4762.04 | CQ3: 3129.9242 | CR3: 3129.9242 | CS3: 2950 | CT3: 2950 | CU3: 26811.03 | CV3: 27191.6 | CW3: 6702.76 | CX3: 20108.27 | CY3: 380.58 | CZ3: 268934.3 | DA3: 268934.3 | DB3: 64817.89 | DC3: 64817.89 | DD3: 54907.02 | DE3: 54907.02 | DF3: 50827.5 | DG3: 4079.53 | DH3: 4079.53 | DI3: 4079.53 | DJ3: 9910.86 | DK3: 125000 | DL3: 125000 | DM3: 125000 | DN3: 125000 | DO3: 125000 | DP3: 30583.42 | DQ3: 30583.42 | DR3: 3941.42 | DS3: 27112 | DT3: 27112 | DU3: 27112 | DV3: 4066.8 | DW3: 4066.8 | DX3: 23045.2 | DY3: 32429.87 | DZ3: 3337.47 | EA3: 5215.35 | EB3: 5215.35 | EC3: 268934.3 | ED3: 470 | EE3: 8750 | EF3: 23473.55 | EG3: 3981.73 | EH3: 3217.43 | EI3: 4044.54 | EJ3: 4044.54 | EK3: 4044.54 | EL3: 4044.54 | EM3: 4044.54 | EN3: 4044.54 | EO3: 4044.54 | EP3: 4044.54 | EQ3: 4044.54 | ER3: 3217.43 | ES3: 827.11 | ET3: 827.11 | EU3: 827.11 | EV3: 446 | EW3: 164000 | EX3: 164000 | EY3: 164000 | EZ3: 164000 | FA3: 164000 | FB3: 6070.86 | FC3: 6068.37 | FD3: 6068.37 | FE3: 2.49 | FF3: 2.49 | FG3: 169484.76 | FH3: 169484.76 | FI3: 169487.26
A4: TOTAL MOLAR FLOW | B4: kmol/h | C4: 62.66 | D4: 577.2 | E4: 112.92 | F4: 639.86 | G4: 112.92 | H4: 752.77 | I4: 752.77 | J4: 752.77 | K4: 752.77 | L4: 752.77 | M4: 752.77 | N4: 219.7 | O4: 972.47 | P4: 704.12 | Q4: 972.47 | R4: 704.12 | S4: 105.62 | T4: 105.62 | U4: 105.62 | V4: 598.5 | Y4: 972.47 | Z4: 972.47 | AA4: 3460.4 | AB4: 2001.47 | AC4: 2001.47 | AD4: 2973.95 | AE4: 3113.34 | AF4: 139.39 | AG4: 298.09 | AH4: 362.62 | AI4: 328.88 | AJ4: 236.23 | AK4: 1 | AL4: 1 | AM4: 1 | AN4: 1 | AO4: 1 | AP4: 5.01 | AQ4: 1458.92 | AR4: 1458.92 | AS4: 1458.92 | AT4: 1458.92 | AU4: 372.1 | AV4: 289.5 | AW4: 290.77084 | AX4: 1.27 | AY4: 486.49 | AZ4: 491.5 | BA4: 491.5 | BB4: 1085.45 | BC4: 1085.45 | BD4: 1524.93 | BE4: 1524.93 | BF4: 616.19 | BG4: 875.82 | BH4: 47.11 | BI4: 47.11 | BJ4: 861.62 | BK4: 861.62 | BL4: 972.43 | BM4: 972.43 | BN4: 1800.15 | BO4: 177.03 | BP4: 727.17 | BQ4: 727.17 | BR4: 727.17 | BS4: 133.22 | BT4: 593.95 | BU4: 439.48 | BV4: 50.93 | BW4: 902.93 | BX4: 902.93 | BY4: 902.93 | BZ4: 902.93 | CA4: 77.42 | CB4: 77.42 | CC4: 825.51 | CD4: 825.51 | CE4: 825.51 | CF4: 704.12 | CG4: 1458.92 | CH4: 423.1 | CI4: 556.32 | CJ4: 556.32 | CK4: 556.32 | CL4: 183.76 | CM4: 183.76 | CN4: 88.97 | CO4: 94.8 | CP4: 259.63 | CQ4: 112.92 | CR4: 112.92 | CS4: 163.75 | CT4: 163.75 | CU4: 1488.25 | CV4: 1509.38 | CW4: 372.06 | CX4: 1116.19 | CY4: 21.13 | CZ4: 704.12 | DA4: 704.12 | DB4: 1034.58 | DC4: 1034.58 | DD4: 484.44 | DE4: 484.44 | DF4: 448.45 | DG4: 35.99 | DH4: 35.99 | DI4: 35.99 | DJ4: 550.14 | DK4: 588.69 | DL4: 588.69 | DM4: 588.69 | DN4: 588.69 | DO4: 588.69 | DP4: 144.03 | DQ4: 144.03 | DR4: 45.65 | DS4: 124.47 | DT4: 124.47 | DU4: 124.47 | DV4: 18.67 | DW4: 18.67 | DX4: 105.8 | DY4: 1800.15 | DZ4: 185.26 | EA4: 289.5 | EB4: 289.5 | EC4: 704.12 | ED4: 26.09 | EE4: 485.7 | EF4: 1302.99 | EG4: 221.02 | EH4: 1584.92 | EI4: 1992.36 | EJ4: 1992.36 | EK4: 1992.36 | EL4: 1992.36 | EM4: 1992.36 | EN4: 1992.36 | EO4: 1992.36 | EP4: 1992.36 | EQ4: 1992.36 | ER4: 1584.92 | ES4: 407.44 | ET4: 407.44 | EU4: 407.44 | EV4: 219.7 | EW4: 6781.83 | EX4: 6781.83 | EY4: 6781.83 | EZ4: 6781.83 | FA4: 6781.83 | FB4: 697.04 | FC4: 696.9 | FD4: 696.9 | FE4: 0.14 | FF4: 0.14 | FG4: 6943.87 | FH4: 6943.87 | FI4: 6944.01
A5: TEMPERATURE | B5: °C | C5: 115 | D5: 115 | E5: 90 | F5: 120.18 | G5: 90.21 | H5: 115.79 | I5: 184.97 | J5: 185 | K5: 184.99 | L5: 187.05 | M5: 187.47 | N5: 109.24 | O5: 186.03 | P5: 281.11 | Q5: 204 | R5: 139.76 | S5: 139.76 | T5: 120 | U5: 120.06 | V5: 139.76 | Y5: 326.78 | Z5: 344.3 | AA5: 417.67 | AB5: 417.67 | AC5: 418.15 | AD5: 388.36 | AE5: 387.28 | AF5: 109.37 | AG5: 109.41 | AH5: 109.42 | AI5: 109.45 | AJ5: 109.46 | AK5: 387.28 | AL5: 393.83 | AM5: 393.83 | AN5: 406.73 | AO5: 410.9 | AP5: 396.73 | AQ5: 417.67 | AR5: 287 | AS5: 287.04 | AT5: 285.17 | AU5: 275.13 | AV5: 205.43 | AW5: 200 | AX5: 152 | AY5: 285.17 | AZ5: 286.43 | BA5: 189 | BB5: 120.79 | BC5: 55 | BD5: 51.97 | BE5: 40 | BF5: 40.41 | BG5: 40.3 | BH5: 39.7 | BI5: 255.99 | BJ5: 40 | BK5: 39.96 | BL5: 285.17 | BM5: 285.41 | BN5: 104 | BO5: 104 | BP5: 95.46 | BQ5: 95.46 | BR5: 96.13 | BS5: 96.51 | BT5: 96.16 | BU5: 48 | BV5: 222.94 | BW5: 282.47 | BX5: 282.3 | BY5: 311 | BZ5: 335 | CA5: 335 | CB5: 334.31 | CC5: 335 | CD5: 335.25 | CE5: 357 | CF5: 298.96 | CG5: 395.66 | CH5: 159.23 | CI5: 143.33 | CJ5: 55 | CK5: 40 | CL5: 39.99 | CM5: 40.28 | CN5: 40.41 | CO5: 40.43 | CP5: 40.02 | CQ5: 39.97 | CR5: 39.31 | CS5: 260 | CT5: 258.67 | CU5: 275.13 | CV5: 260 | CW5: 198.9 | CX5: 198.9 | CY5: 152 | CZ5: 330.49 | DA5: 331 | DB5: 129.2 | DC5: 92.4 | DD5: 92.39 | DE5: 92.95 | DF5: 92.95 | DG5: 92.95 | DH5: 39.94 | DI5: 40 | DJ5: 92.58 | DK5: 234.36 | DL5: 234.5 | DM5: 214 | DN5: 181 | DO5: 181 | DP5: 234.39 | DQ5: 234.39 | DR5: 231.78 | DS5: 223.17 | DT5: 223.81 | DU5: 129.34 | DV5: 50 | DW5: 50.04 | DX5: 129.35 | DY5: 152 | DZ5: 199.23 | EA5: 166.94 | EB5: 158.41 | EC5: 214 | ED5: 221.39 | EE5: 221.39 | EF5: 199.23 | EG5: 260 | EH5: 40 | EI5: 40 | EJ5: 40 | EK5: 108.03 | EL5: 40 | EM5: 40 | EN5: 107.73 | EO5: 40 | EP5: 40 | EQ5: 109.17 | ER5: 109.18 | ES5: 109.18 | ET5: 38.84 | EU5: 40 | EV5: 109.18 | EW5: 40 | EX5: 40 | EY5: 40 | EZ5: 50 | FA5: 50 | FB5: 50 | FC5: 50 | FD5: 50 | FE5: 50 | FF5: 50 | FG5: 50 | FH5: 50 | FI5: 50
A6: PRESSURE | B6: MPa(g) | C6: 0.4 | D6: 0.4 | E6: 0.4 | F6: 0.2 | G6: 0.2 | H6: 0.2 | I6: 0.9 | J6: 0.6 | K6: 0.42 | L6: 16.06 | M6: 15.1 | N6: 15.1 | O6: 15.1 | P6: 1.32 | Q6: 15.03 | R6: 1.15 | S6: 1.15 | T6: 1.12 | U6: 1 | V6: 1.15 | Y6: 14.7 | Z6: 14.36 | AA6: 13.83 | AB6: 13.86 | AC6: 14.4 | AD6: 14.21 | AE6: 14.21 | AF6: 14.21 | AG6: 14.01 | AH6: 13.99 | AI6: 13.83 | AJ6: 13.82 | AK6: 14.18 | AL6: 13.98 | AM6: 13.98 | AN6: 13.8 | AO6: 13.79 | AP6: 2.99 | AQ6: 13.85 | AR6: 13.47 | AS6: 13.37 | AT6: 2.99 | AU6: 1.25 | AV6: 0.33 | AW6: 0.3 | AX6: 2.38 | AY6: 2.99 | AZ6: 2.99 | BA6: 2.88 | BB6: 2.88 | BC6: 2.85 | BD6: 2.85 | BE6: 2.81 | BF6: 0.91 | BG6: 0.9 | BH6: 1.28 | BI6: 1.21 | BJ6: 2.81 | BK6: 2.8 | BL6: 2.99 | BM6: 1.22 | BN6: 2.49 | BO6: 2.5 | BP6: 0.4 | BQ6: 0.4 | BR6: 3.01 | BS6: 1.06 | BT6: 2.9 | BU6: 2.86 | BV6: 1.07 | BW6: 1.09 | BX6: 0.3 | BY6: 0.23 | BZ6: 0.2 | CA6: 0.2 | CB6: 0.08 | CC6: 0.2 | CD6: 0.54 | CE6: 0.2 | CF6: 1.36 | CG6: 13.78 | CH6: 1.06 | CI6: 1.06 | CJ6: 1.02 | CK6: 0.99 | CL6: 1 | CM6: 1.38 | CN6: 1.06 | CO6: 1 | CP6: 0.91 | CQ6: 0.98 | CR6: 0.9 | CS6: 1.2 | CT6: 1.09 | CU6: 1.25 | CV6: 1.2 | CW6: 1.42 | CX6: 1.42 | CY6: 2.38 | CZ6: 0.14 | DA6: 1.48 | DB6: 0.08 | DC6: 0.04 | DD6: 0.06 | DE6: 1.16 | DF6: 1.15 | DG6: 1.16 | DH6: 1.12 | DI6: 1 | DJ6: 0.4 | DK6: 0.24 | DL6: 0.53 | DM6: 0.46 | DN6: 0.39 | DO6: 0.09 | DP6: 0.09 | DQ6: 0.09 | DR6: 0.09 | DS6: 0.11 | DT6: 1.22 | DU6: 1.13 | DV6: 1.08 | DW6: 1 | DX6: 1.1 | DY6: 2.38 | DZ6: 1.43 | EA6: 0.63 | EB6: 0.38 | EC6: 1.26 | ED6: 0.3 | EE6: 0.3 | EF6: 1.43 | EG6: 1.2 | EH6: 2.4 | EI6: 2.39 | EJ6: 2.38 | EK6: 4.48 | EL6: 4.41 | EM6: 4.4 | EN6: 8.17 | EO6: 8.1 | EP6: 8.1 | EQ6: 15.12 | ER6: 15.07 | ES6: 15.08 | ET6: 15.05 | EU6: 2.39 | EV6: 15.07 | EW6: 0.7 | EX6: 0.4 | EY6: 0.4 | EZ6: 3.09 | FA6: 2.98 | FB6: 2.78 | FC6: 2.78 | FD6: 2.7 | FE6: 2.7 | FF6: 0.7 | FG6: 2.8 | FH6: 0.7 | FI6: 0.7
A7: ENTHALPY | B7: kJ/kg | C7: -1954.7 | D7: -1938.69 | E7: -2005.69 | F7: -1940.31 | G7: -2005.69 | H7: -1950.12 | I7: -1787.08 | J7: -1787.08 | K7: -1787.08 | L7: -1763.91 | M7: -1763.91 | N7: 1184.49 | O7: -1759.67 | P7: -1515.95 | Q7: -1713.95 | R7: -1891.17 | S7: -1891.17 | T7: -1937.47 | U7: -1937.47 | V7: -1891.17 | Y7: -1369.63 | Z7: -1316.91 | AA7: -1039.9 | AB7: -1039.9 | AC7: -1038.25 | AD7: -1155.15 | AE7: -1154.26 | AF7: 1184.49 | AG7: 1184.49 | AH7: 1184.49 | AI7: 1184.49 | AJ7: 1184.49 | AK7: -383.73 | AL7: -457.06 | AM7: -457.06 | AN7: -555.85 | AO7: -585.74 | AP7: -510.54 | AQ7: -1039.9 | AR7: -1454.64 | AS7: -1454.64 | AT7: -1467.97 | AU7: -12937.4 | AV7: -13054.8 | AW7: -13064.55 | AX7: -15283.46 | AY7: -913.34 | AZ7: -909.86 | BA7: -1163.94 | BB7: -7755.02 | BC7: -8045.51 | BD7: -7137.58 | BE7: -7184.24 | BF7: -15038.04 | BG7: -15046.91 | BH7: -2159.8 | BI7: -1459.16 | BJ7: -1621.61 | BK7: -1621.61 | BL7: -1491.24 | BM7: -1491.24 | BN7: -15487.73 | BO7: -15542.66 | BP7: -15581.92 | BQ7: -15581.92 | BR7: -15576.78 | BS7: -15576.78 | BT7: -15576.78 | BU7: -2217.78 | BV7: -1661.64 | BW7: -1539.27 | BX7: -1539.27 | BY7: -1452.16 | BZ7: -1375.93 | CA7: -2217.41 | CB7: -2217.41 | CC7: -1353.54 | CD7: -1352.58 | CE7: -1283.44 | CF7: -1463.26 | CG7: -1113.24 | CH7: -2706.75 | CI7: -4045.41 | CJ7: -4659.97 | CK7: -4709.53 | CL7: -2165.93 | CM7: -2164.99 | CN7: -2164.99 | CO7: -2164.99 | CP7: -15067.97 | CQ7: -1287.6 | CR7: -1287.6 | CS7: -13003.06 | CT7: -13003.06 | CU7: -12937.39 | CV7: -12970.23 | CW7: -13134.41 | CX7: -13134.41 | CY7: -15283.46 | CZ7: -1368.33 | DA7: -1365.82 | DB7: -3448.21 | DC7: -4141.4 | DD7: -2073.88 | DE7: -2071.65 | DF7: -2071.65 | DG7: -2071.65 | DH7: -2192.73 | DI7: -2192.73 | DJ7: -15594.55 | DK7: -1659.23 | DL7: -1658.66 | DM7: -1716.04 | DN7: -1804.6 | DO7: -1804.86 | DP7: -1659.23 | DQ7: -1659.23 | DR7: -2790.33 | DS7: -1692.41 | DT7: -1689.87 | DU7: -1934.21 | DV7: -2110.94 | DW7: -2110.94 | DX7: -1934.21 | DY7: -15283.46 | DZ7: -13134.41 | EA7: -13160.88 | EB7: -13160.88 | EC7: -1703.53 | ED7: -13058.92 | EE7: -13058.92 | EF7: -13134.41 | EG7: -13003.06 | EH7: 173.76 | EI7: 173.76 | EJ7: 173.76 | EK7: 1139.12 | EL7: 174.89 | EM7: 174.89 | EN7: 1143.82 | EO7: 178.59 | EP7: 178.59 | EQ7: 1184.49 | ER7: 1184.49 | ES7: 1184.5 | ET7: 173.75 | EU7: 173.75 | EV7: 1184.49 | EW7: -1042.59 | EX7: -1042.59 | EY7: -1042.59 | EZ7: -1039.2 | FA7: -1039.2 | FB7: -2539.36 | FC7: -2533.94 | FD7: -2533.94 | FE7: -15749.02 | FF7: -15749.02 | FG7: -997.97 | FH7: -997.97 | FI7: -11762.43
A8: ENERGY | B8: MW | C8: -14.48 | D8: -127.32 | E8: -25.87 | F8: -141.8 | G8: -25.87 | H8: -167.67 | I8: -153.65 | J8: -153.65 | K8: -153.65 | L8: -151.66 | M8: -151.66 | N8: 0.15 | O8: -151.51 | P8: -113.25 | Q8: -147.58 | R8: -141.28 | S8: -21.19 | T8: -21.71 | U8: -21.71 | V8: -120.09 | Y8: -117.93 | Z8: -113.39 | AA8: -214.2 | AB8: -123.89 | AC8: -123.69 | AD8: -237.08 | AE8: -236.99 | AF8: 0.09 | AG8: 0.2 | AH8: 0.24 | AI8: 0.22 | AJ8: 0.16 | AK8: 0 | AL8: 0 | AM8: 0 | AN8: 0 | AO8: 0 | AP8: -0.02 | AQ8: -90.31 | AR8: -126.32 | AS8: -126.32 | AT8: -127.48 | AU8: -24.09 | AV8: -18.91 | AW8: -19.00989 | AX8: -0.1 | AY8: -3.19 | AZ8: -3.21 | BA8: -4.11 | BB8: -50.4 | BC8: -52.29 | BD8: -54.95 | BE8: -55.31 | BF8: -47.23 | BG8: -67.16 | BH8: -2.76 | BI8: -1.87 | BJ8: -5.32 | BK8: -5.32 | BL8: -124.29 | BM8: -124.29 | BN8: -139.52 | BO8: -13.77 | BP8: -56.7 | BQ8: -56.7 | BR8: -56.68 | BS8: -10.38 | BT8: -46.3 | BU8: -2.66 | BV8: -3.02 | BW8: -128.62 | BX8: -128.62 | BY8: -121.34 | BZ8: -114.97 | CA8: -4.8 | CB8: -4.8 | CC8: -110.17 | CD8: -110.09 | CE8: -104.46 | CF8: -109.31 | CG8: -96.68 | CH8: -15.54 | CI8: -25.93 | CJ8: -29.87 | CK8: -30.19 | CL8: -9.13 | CM8: -9.13 | CN8: -4.42 | CO8: -4.71 | CP8: -19.93 | CQ8: -1.12 | CR8: -1.12 | CS8: -10.66 | CT8: -10.66 | CU8: -96.35 | CV8: -97.97 | CW8: -24.45 | CX8: -73.36 | CY8: -1.62 | CZ8: -102.22 | DA8: -102.03 | DB8: -62.08 | DC8: -74.57 | DD8: -31.63 | DE8: -31.6 | DF8: -29.25 | DG8: -2.35 | DH8: -2.48 | DI8: -2.48 | DJ8: -42.93 | DK8: -57.61 | DL8: -57.59 | DM8: -59.58 | DN8: -62.66 | DO8: -62.67 | DP8: -14.1 | DQ8: -14.1 | DR8: -3.05 | DS8: -12.75 | DT8: -12.73 | DU8: -14.57 | DV8: -2.38 | DW8: -2.38 | DX8: -12.38 | DY8: -137.68 | DZ8: -12.18 | EA8: -19.07 | EB8: -19.07 | EC8: -127.26 | ED8: -1.7 | EE8: -31.74 | EF8: -85.64 | EG8: -14.38 | EH8: 0.16 | EI8: 0.2 | EJ8: 0.2 | EK8: 1.28 | EL8: 0.2 | EM8: 0.2 | EN8: 1.29 | EO8: 0.2 | EP8: 0.2 | EQ8: 1.33 | ER8: 1.06 | ES8: 0.27 | ET8: 0.04 | EU8: 0.04 | EV8: 0.15 | EW8: -47.5 | EX8: -47.5 | EY8: -47.5 | EZ8: -47.34 | FA8: -47.34 | FB8: -4.28 | FC8: -4.27 | FD8: -4.27 | FE8: -0.01 | FF8: -0.01 | FG8: -46.98 | FH8: -46.98 | FI8: -553.77
A9: SPECIFIC HEAT | B9: kJ/(kg-°C) | C9: 2.17 | D9: 2.25 | E9: 2.12 | F9: 2.24 | G9: 2.12 | H9: 2.22 | I9: 2.49 | J9: 2.49 | K9: 2.49 | L9: 2.49 | M9: 2.49 | N9: 14.36 | O9: 2.51 | P9: 2.92 | Q9: 2.58 | R9: 2.38 | S9: 2.38 | T9: 2.3 | U9: 2.3 | V9: 2.38 | Y9: 3 | Z9: 3.06 | AA9: 3.36 | AB9: 3.36 | AC9: 3.36 | AD9: 3.24 | AE9: 3.25 | AF9: 14.35 | AG9: 14.35 | AH9: 14.35 | AI9: 14.35 | AJ9: 14.35 | AK9: 3.55 | AL9: 3.42 | AM9: 3.42 | AN9: 3.24 | AO9: 3.22 | AP9: 3.25 | AQ9: 3.36 | AR9: 2.95 | AS9: 2.95 | AT9: 2.93 | AU9: 2.26 | AV9: 2.12 | AW9: 2.11 | AX9: 4.31 | AY9: 2.49 | AZ9: 2.49 | BA9: 2.32 | BB9: 3.21 | BC9: 3.17 | BD9: 3.22 | BE9: 3.21 | BF9: 4.22 | BG9: 4.22 | BH9: 2.13 | BI9: 2.71 | BJ9: 2.68 | BK9: 2.68 | BL9: 2.95 | BM9: 2.94 | BN9: 4.22 | BO9: 4.4 | BP9: 4.39 | BQ9: 4.39 | BR9: 4.38 | BS9: 4.39 | BT9: 4.38 | BU9: 3.63 | BV9: 2.75 | BW9: 2.94 | BX9: 2.94 | BY9: 3.04 | BZ9: 3.12 | CA9: 2.76 | CB9: 2.75 | CC9: 3.13 | CD9: 3.13 | CE9: 3.21 | CF9: 2.98 | CG9: 3.3 | CH9: 2.12 | CI9: 2.34 | CJ9: 2.55 | CK9: 2.52 | CL9: 2.18 | CM9: 2.18 | CN9: 2.18 | CO9: 2.18 | CP9: 4.22 | CQ9: 1.58 | CR9: 1.57 | CS9: 2.08 | CT9: 2.07 | CU9: 2.26 | CV9: 2.3 | CW9: 2.83 | CX9: 2.83 | CY9: 4.31 | CZ9: 3.1 | DA9: 3.09 | DB9: 2.06 | DC9: 2.69 | DD9: 2.39 | DE9: 2.38 | DF9: 2.38 | DG9: 2.38 | DH9: 2.12 | DI9: 2.12 | DJ9: 4.38 | DK9: 2.84 | DL9: 2.84 | DM9: 2.75 | DN9: 2.61 | DO9: 2.61 | DP9: 2.84 | DQ9: 2.84 | DR9: 2.39 | DS9: 2.79 | DT9: 2.78 | DU9: 2.39 | DV9: 2.04 | DW9: 2.04 | DX9: 2.39 | DY9: 4.31 | DZ9: 2.83 | EA9: 2.46 | EB9: 2.28 | EC9: 2.67 | ED9: 1.99 | EE9: 1.99 | EF9: 2.83 | EG9: 2.08 | EH9: 14.1 | EI9: 14.1 | EJ9: 14.1 | EK9: 14.2 | EL9: 14.16 | EM9: 14.16 | EN9: 14.26 | EO9: 14.26 | EP9: 14.26 | EQ9: 14.37 | ER9: 14.36 | ES9: 14.36 | ET9: 14.41 | EU9: 14.1 | EV9: 14.36 | EW9: 3.8 | EX9: 3.8 | EY9: 3.8 | EZ9: 3.81 | FA9: 3.81 | FB9: 4.16 | FC9: 4.16 | FD9: 4.16 | FE9: 4.32 | FF9: 4.32 | FG9: 3.77 | FH9: 3.77 | FI9: 3.78
A10: CRITICAL TEMP. | B10: °C | C10: 629.92 | D10: 593.23 | E10: 596.82 | F10: 596.82 | G10: 596.82 | H10: 596.82 | I10: 596.82 | J10: 596.82 | K10: 596.82 | L10: 596.82 | M10: 596.82 | N10: -239.55 | O10: 407.87 | P10: 563.4 | Q10: 407.87 | R10: 563.4 | S10: 563.4 | T10: 563.4 | U10: 563.4 | V10: 563.4 | Y10: 407.87 | Z10: 407.87 | AA10: 297.26 | AB10: 297.26 | AC10: 297.26 | AD10: 333.43 | AE10: 307.78 | AF10: -239.55 | AG10: -239.55 | AH10: -239.55 | AI10: -239.55 | AJ10: -239.55 | AK10: -141.74 | AL10: -128.88 | AM10: -128.88 | AN10: -101.52 | AO10: -92.68 | AP10: -116.2 | AQ10: 297.26 | AR10: 297.26 | AS10: 297.26 | AT10: 297.26 | AU10: 374.15 | AV10: 374.15 | AW10: 374.15 | AX10: 374.15 | AY10: -45.67 | AZ10: -46.39 | BA10: -46.39 | BB10: 183.72 | BC10: 183.72 | BD10: 83.33 | BE10: 83.33 | BF10: 364.28 | BG10: 364.42 | BH10: 226.74 | BI10: 226.74 | BJ10: -125.44 | BK10: -125.44 | BL10: 468.83 | BM10: 468.83 | BN10: 374.15 | BO10: 374.15 | BP10: 374.15 | BQ10: 374.15 | BR10: 374.15 | BS10: 374.15 | BT10: 374.15 | BU10: -164.64 | BV10: 294.24 | BW10: 527.36 | BX10: 527.36 | BY10: 527.36 | BZ10: 527.36 | CA10: 379.4 | CB10: 379.4 | CC10: 541.24 | CD10: 541.24 | CE10: 541.24 | CF10: 563.4 | CG10: 297.26 | CH10: 203.06 | CI10: 244.03 | CJ10: 244.03 | CK10: 244.03 | CL10: 216.51 | CM10: 216.51 | CN10: 216.51 | CO10: 216.51 | CP10: 364.74 | CQ10: 11.29 | CR10: 11.29 | CS10: 374.15 | CT10: 374.15 | CU10: 374.15 | CV10: 374.15 | CW10: 374.15 | CX10: 374.15 | CY10: 374.15 | CZ10: 563.4 | DA10: 563.4 | DB10: 337.68 | DC10: 337.68 | DD10: 296.27 | DE10: 296.27 | DF10: 296.27 | DG10: 296.27 | DH10: 296.27 | DI10: 296.27 | DJ10: 374.15 | DK10: 431.41 | DL10: 431.41 | DM10: 431.41 | DN10: 431.41 | DO10: 431.41 | DP10: 431.41 | DQ10: 431.41 | DR10: 382.05 | DS10: 437.51 | DT10: 437.51 | DU10: 437.51 | DV10: 437.51 | DW10: 437.51 | DX10: 437.51 | DY10: 374.15 | DZ10: 374.15 | EA10: 374.15 | EB10: 374.15 | EC10: 563.4 | ED10: 374.15 | EE10: 374.15 | EF10: 374.15 | EG10: 374.15 | EH10: -239.55 | EI10: -239.55 | EJ10: -239.55 | EK10: -239.55 | EL10: -239.55 | EM10: -239.55 | EN10: -239.55 | EO10: -239.55 | EP10: -239.55 | EQ10: -239.55 | ER10: -239.55 | ES10: -239.55 | ET10: -239.55 | EU10: -239.55 | EV10: -239.55 | EW10: 375.82 | EX10: 375.82 | EY10: 375.82 | EZ10: 375.82 | FA10: 375.82 | FB10: -177.48 | FC10: -177.59 | FD10: -177.59 | FE10: 374.07 | FF10: 374.07 | FG10: 369.21 | FH10: 369.21 | FI10: 369.21
A11: CRITICAL PRESS. | B11: MPa(g) | C11: 1 | D11: 0.98 | E11: 0.98 | F11: 0.98 | G11: 0.98 | H11: 0.98 | I11: 0.98 | J11: 0.98 | K11: 0.98 | L11: 0.98 | M11: 0.98 | N11: 1.22 | O11: 1.04 | P11: 1.18 | Q11: 1.04 | R11: 1.18 | S11: 1.18 | T11: 1.18 | U11: 1.18 | V11: 1.18 | Y11: 1.04 | Z11: 1.04 | AA11: 2.68 | AB11: 2.68 | AC11: 2.68 | AD11: 2.14 | AE11: 2.1 | AF11: 1.22 | AG11: 1.22 | AH11: 1.22 | AI11: 1.22 | AJ11: 1.22 | AK11: 2.75 | AL11: 2.9 | AM11: 2.9 | AN11: 3.22 | AO11: 3.3 | AP11: 3.04 | AQ11: 2.68 | AR11: 2.68 | AS11: 2.68 | AT11: 2.68 | AU11: 22.02 | AV11: 22.02 | AW11: 22.02 | AX11: 22.02 | AY11: 4.47 | AZ11: 4.45 | BA11: 4.45 | BB11: 14.07 | BC11: 14.07 | BD11: 10.72 | BE11: 10.72 | BF11: 21.56 | BG11: 21.56 | BH11: 3.73 | BI11: 3.73 | BJ11: 3.35 | BK11: 3.35 | BL11: 1.79 | BM11: 1.79 | BN11: 22.02 | BO11: 22.02 | BP11: 22.02 | BQ11: 22.02 | BR11: 22.02 | BS11: 22.02 | BT11: 22.02 | BU11: 2.46 | BV11: 3.23 | BW11: 2.21 | BX11: 2.21 | BY11: 2.21 | BZ11: 2.21 | CA11: 12.21 | CB11: 12.21 | CC11: 1.27 | CD11: 1.27 | CE11: 1.27 | CF11: 1.18 | CG11: 2.68 | CH11: 9.66 | CI11: 12.62 | CJ11: 12.62 | CK11: 12.62 | CL11: 3.98 | CM11: 3.98 | CN11: 3.98 | CO11: 3.98 | CP11: 21.58 | CQ11: 6.08 | CR11: 6.08 | CS11: 22.02 | CT11: 22.02 | CU11: 22.02 | CV11: 22.02 | CW11: 22.02 | CX11: 22.02 | CY11: 22.02 | CZ11: 1.18 | DA11: 1.18 | DB11: 12.94 | DC11: 12.94 | DD11: 2.63 | DE11: 2.63 | DF11: 2.63 | DG11: 2.63 | DH11: 2.63 | DI11: 2.63 | DJ11: 22.02 | DK11: 1.76 | DL11: 1.76 | DM11: 1.76 | DN11: 1.76 | DO11: 1.76 | DP11: 1.76 | DQ11: 1.76 | DR11: 13.32 | DS11: 1.77 | DT11: 1.77 | DU11: 1.77 | DV11: 1.77 | DW11: 1.77 | DX11: 1.77 | DY11: 22.02 | DZ11: 22.02 | EA11: 22.02 | EB11: 22.02 | EC11: 1.18 | ED11: 22.02 | EE11: 22.02 | EF11: 22.02 | EG11: 22.02 | EH11: 1.22 | EI11: 1.22 | EJ11: 1.22 | EK11: 1.22 | EL11: 1.22 | EM11: 1.22 | EN11: 1.22 | EO11: 1.22 | EP11: 1.22 | EQ11: 1.22 | ER11: 1.22 | ES11: 1.22 | ET11: 1.22 | EU11: 1.22 | EV11: 1.22 | EW11: 20.89 | EX11: 20.89 | EY11: 20.89 | EZ11: 20.89 | FA11: 20.89 | FB11: 2.13 | FC11: 2.12 | FD11: 2.12 | FE11: 22.02 | FF11: 22.02 | FG11: 20.6 | FH11: 20.6 | FI11: 20.6
A12: PHASE | C12: LIQUID | D12: LIQUID | E12: LIQUID | F12: LIQUID | G12: LIQUID | H12: LIQUID | I12: LIQUID | J12: LIQUID | K12: LIQUID | L12: LIQUID | M12: LIQUID | N12: VAPOR | O12: MIXED | P12: LIQUID | Q12: MIXED | R12: LIQUID | S12: LIQUID | T12: LIQUID | U12: LIQUID | V12: LIQUID | Y12: LIQUID | Z12: LIQUID | AA12: LIQUID | AB12: LIQUID | AC12: LIQUID | AD12: LIQUID | AE12: LIQUID | AF12: VAPOR | AG12: VAPOR | AH12: VAPOR | AI12: VAPOR | AJ12: VAPOR | AK12: VAPOR | AL12: VAPOR | AM12: VAPOR | AN12: VAPOR | AO12: VAPOR | AP12: VAPOR | AQ12: LIQUID | AR12: MIXED | AS12: MIXED | AT12: MIXED | AU12: VAPOR | AV12: VAPOR | AW12: VAPOR | AX12: LIQUID | AY12: VAPOR | AZ12: MIXED | BA12: MIXED | BB12: MIXED | BC12: MIXED | BD12: MIXED | BE12: MIXED | BF12: MIXED | BG12: MIXED | BH12: MIXED | BI12: MIXED | BJ12: VAPOR | BK12: VAPOR | BL12: LIQUID | BM12: MIXED | BN12: LIQUID | BO12: LIQUID | BP12: LIQUID | BQ12: LIQUID | BR12: LIQUID | BS12: LIQUID | BT12: LIQUID | BU12: VAPOR | BV12: MIXED | BW12: LIQUID | BX12: MIXED | BY12: MIXED | BZ12: MIXED | CA12: VAPOR | CB12: VAPOR | CC12: LIQUID | CD12: LIQUID | CE12: MIXED | CF12: LIQUID | CG12: LIQUID | CH12: MIXED | CI12: MIXED | CJ12: MIXED | CK12: MIXED | CL12: LIQUID | CM12: LIQUID | CN12: LIQUID | CO12: LIQUID | CP12: LIQUID | CQ12: VAPOR | CR12: VAPOR | CS12: VAPOR | CT12: VAPOR | CU12: VAPOR | CV12: VAPOR | CW12: VAPOR | CX12: VAPOR | CY12: LIQUID | CZ12: LIQUID | DA12: LIQUID | DB12: VAPOR | DC12: LIQUID | DD12: LIQUID | DE12: LIQUID | DF12: LIQUID | DG12: LIQUID | DH12: LIQUID | DI12: LIQUID | DJ12: LIQUID | DK12: LIQUID | DL12: LIQUID | DM12: LIQUID | DN12: LIQUID | DO12: LIQUID | DP12: LIQUID | DQ12: LIQUID | DR12: VAPOR | DS12: LIQUID | DT12: LIQUID | DU12: LIQUID | DV12: LIQUID | DW12: LIQUID | DX12: LIQUID | DY12: LIQUID | DZ12: VAPOR | EA12: VAPOR | EB12: VAPOR | EC12: LIQUID | ED12: VAPOR | EE12: VAPOR | EF12: VAPOR | EG12: VAPOR | EH12: VAPOR | EI12: VAPOR | EJ12: VAPOR | EK12: VAPOR | EL12: VAPOR | EM12: VAPOR | EN12: VAPOR | EO12: VAPOR | EP12: VAPOR | EQ12: VAPOR | ER12: VAPOR | ES12: VAPOR | ET12: VAPOR | EU12: VAPOR | EV12: VAPOR | EW12: LIQUID | EX12: LIQUID | EY12: LIQUID | EZ12: LIQUID | FA12: LIQUID | FB12: MIXED | FC12: VAPOR | FD12: VAPOR | FE12: LIQUID | FF12: MIXED | FG12: LIQUID | FH12: MIXED | FI12: MIXED
A13: VAPOR FRACTION | C13: 0 | D13: 0 | E13: 0 | F13: 0 | G13: 0 | H13: 0 | I13: 0 | J13: 0 | K13: 0 | L13: 0 | M13: 0 | N13: 1 | O13: 0 | P13: 0 | Q13: 0 | R13: 0 | S13: 0 | T13: 0 | U13: 0 | V13: 0 | Y13: 0 | Z13: 0 | AA13: 0 | AB13: 0 | AC13: 0 | AD13: 0 | AE13: 0 | AF13: 1 | AG13: 1 | AH13: 1 | AI13: 1 | AJ13: 1 | AK13: 1 | AL13: 1 | AM13: 1 | AN13: 1 | AO13: 1 | AP13: 1 | AQ13: 0 | AR13: 0 | AS13: 0 | AT13: 0.04 | AU13: 1 | AV13: 1 | AW13: 1 | AX13: 0 | AY13: 1 | AZ13: 1 | BA13: 0.91 | BB13: 0.45 | BC13: 0.32 | BD13: 0.44 | BE13: 0.43 | BF13: 0 | BG13: 0 | BH13: 0.01 | BI13: 0.7 | BJ13: 1 | BK13: 1 | BL13: 0 | BM13: 0.01 | BN13: 0 | BO13: 0 | BP13: 0 | BQ13: 0 | BR13: 0 | BS13: 0 | BT13: 0 | BU13: 1 | BV13: 0.15 | BW13: 0 | BX13: 0.01 | BY13: 0.01 | BZ13: 0.03 | CA13: 1 | CB13: 1 | CC13: 0 | CD13: 0 | CE13: 0 | CF13: 0 | CG13: 0 | CH13: 1 | CI13: 0.79 | CJ13: 0.17 | CK13: 0.14 | CL13: 0 | CM13: 0 | CN13: 0 | CO13: 0 | CP13: 0 | CQ13: 1 | CR13: 1 | CS13: 1 | CT13: 1 | CU13: 1 | CV13: 1 | CW13: 1 | CX13: 1 | CY13: 0 | CZ13: 0 | DA13: 0 | DB13: 1 | DC13: 0 | DD13: 0 | DE13: 0 | DF13: 0 | DG13: 0 | DH13: 0 | DI13: 0 | DJ13: 0 | DK13: 0 | DL13: 0 | DM13: 0 | DN13: 0 | DO13: 0 | DP13: 0 | DQ13: 0 | DR13: 1 | DS13: 0 | DT13: 0 | DU13: 0 | DV13: 0 | DW13: 0 | DX13: 0 | DY13: 0 | DZ13: 1 | EA13: 1 | EB13: 1 | EC13: 0 | ED13: 1 | EE13: 1 | EF13: 1 | EG13: 1 | EH13: 1 | EI13: 1 | EJ13: 1 | EK13: 1 | EL13: 1 | EM13: 1 | EN13: 1 | EO13: 1 | EP13: 1 | EQ13: 1 | ER13: 1 | ES13: 1 | ET13: 1 | EU13: 1 | EV13: 1 | EW13: 0 | EX13: 0 | EY13: 0 | EZ13: 0 | FA13: 0 | FB13: 1 | FC13: 1 | FD13: 1 | FE13: 0 | FF13: 3.6e-06 | FG13: 0 | FH13: 8.79e-05 | FI13: 0
A14: LIQ. FLOW @ P&T | B14: m³/h | C14: 30.28 | D14: 282.25 | E14: 53.84 | F14: 312.69 | G14: 53.87 | H14: 366.55 | I14: 388.76 | J14: 388.8 | K14: 388.79 | L14: 383.59 | M14: 384.04 | O14: 390.2 | P14: 389.28 | Q14: 396.81 | R14: 337.65 | S14: 50.65 | T14: 49.76 | U14: 49.77 | V14: 287 | Y14: 452.85 | Z14: 461.92 | AA14: 1470.82 | AB14: 850.28 | AC14: 845.04 | AD14: 1338.07 | AE14: 1343.3 | AQ14: 619.9 | AR14: 509.28 | AS14: 509.1 | AT14: 455.8 | AX14: 0.03 | AZ14: 0.01 | BA14: 1.73 | BB14: 14.95 | BC14: 18.13 | BD14: 17.4 | BE14: 17.98 | BF14: 11.52 | BG14: 16.36 | BH14: 6.4 | BI14: 2.31 | BL14: 455.8 | BM14: 446.09 | BN14: 33.92 | BO14: 3.37 | BP14: 13.76 | BQ14: 13.76 | BR14: 13.75 | BS14: 2.52 | BT14: 11.24 | BV14: 8.85 | BW14: 447.55 | BX14: 442.83 | BY14: 454.91 | BZ14: 463.08 | CC14: 463.08 | CD14: 462.76 | CE14: 476.54 | CF14: 397.4 | CG14: 601.23 | CH14: 0 | CI14: 6.95 | CJ14: 26.58 | CK14: 27.05 | CL14: 22.2 | CM14: 22.19 | CN14: 10.75 | CO14: 11.46 | CP14: 4.85 | CY14: 0.42 | CZ14: 414.21 | DA14: 413.21 | DC14: 93.22 | DD14: 82.83 | DE14: 82.65 | DF14: 76.51 | DG14: 6.14 | DH14: 5.75 | DI14: 5.75 | DJ14: 10.39 | DK14: 194.25 | DL14: 194.08 | DM14: 188.82 | DN14: 181.22 | DO14: 181.36 | DP14: 47.56 | DQ14: 47.55 | DS14: 41.25 | DT14: 41.14 | DU14: 36.87 | DV14: 5.12 | DW14: 5.12 | DX14: 31.34 | DY14: 35.41 | EC14: 362.38 | EW14: 162.41 | EX14: 162.41 | EY14: 162.41 | EZ14: 162.5 | FA14: 162.5 | FB14: 0 | FE14: 0 | FF14: 0 | FG14: 161.93 | FH14: 161.92 | FI14: 176.57
A15: LIQ. FLOW @ 15.6°C | B15: m³/h | C15: 28.16 | D15: 260.38 | E15: 50.92 | F15: 288.57 | G15: 50.92 | H15: 339.49 | I15: 339.49 | J15: 339.49 | K15: 339.49 | L15: 339.49 | M15: 339.49 | O15: 344.24 | P15: 304.3 | Q15: 344.46 | R15: 304.3 | S15: 45.65 | T15: 45.65 | U15: 45.65 | V15: 258.66 | Y15: 346.52 | Z15: 346.52 | AA15: 869.32 | AB15: 502.81 | AC15: 502.81 | AD15: 846.45 | AE15: 851.69 | AQ15: 366.51 | AR15: 363.48 | AS15: 363.33 | AT15: 344.71 | AX15: 0.02 | AZ15: 0.01 | BA15: 1.43 | BB15: 13.2 | BC15: 16.79 | BD15: 16.19 | BE15: 16.88 | BF15: 11.3 | BG15: 16.05 | BH15: 6.2 | BI15: 1.71 | BL15: 344.71 | BM15: 340.85 | BN15: 32.47 | BO15: 3.14 | BP15: 12.91 | BQ15: 12.91 | BR15: 12.91 | BS15: 2.37 | BT15: 10.55 | BV15: 6.89 | BW15: 346.51 | BX15: 342.71 | BY15: 339.78 | BZ15: 335.25 | CC15: 335.25 | CD15: 335.25 | CE15: 334.45 | CF15: 304.3 | CG15: 366.51 | CH15: 0 | CI15: 5.54 | CJ15: 24.04 | CK15: 25.03 | CL15: 21.44 | CM15: 21.44 | CN15: 10.38 | CO15: 11.06 | CP15: 4.75 | CY15: 0.38 | CZ15: 304.3 | DA15: 304.3 | DC15: 80.79 | DD15: 75.38 | DE15: 75.38 | DF15: 69.78 | DG15: 5.6 | DH15: 5.6 | DI15: 5.6 | DJ15: 9.77 | DK15: 153.3 | DL15: 153.3 | DM15: 153.3 | DN15: 153.3 | DO15: 153.29 | DP15: 37.51 | DQ15: 37.51 | DS15: 33.12 | DT15: 33.12 | DU15: 33.12 | DV15: 4.97 | DW15: 4.97 | DX15: 28.15 | DY15: 32.47 | EC15: 304.3 | EW15: 159.44 | EX15: 159.44 | EY15: 159.44 | EZ15: 159.44 | FA15: 159.44 | FB15: 0 | FE15: 0 | FF15: 0 | FG15: 158.04 | FH15: 158.03 | FI15: 169.71
A16: LIQUID DENSITY | B16: kg/m³ | C16: 880.95 | D16: 837.63 | E16: 862.28 | F16: 841.4 | G16: 861.9 | H16: 844.42 | I16: 796.18 | J16: 796.1 | K16: 796.12 | L16: 806.91 | M16: 805.96 | O16: 793.98 | P16: 690.85 | Q16: 780.79 | R16: 796.5 | S16: 796.5 | T16: 810.68 | U16: 810.57 | V16: 796.5 | Y16: 684.49 | Z16: 671.05 | AA16: 504.16 | AB16: 504.42 | AC16: 507.54 | AD16: 552.19 | AE16: 550.25 | AQ16: 504.32 | AR16: 611.62 | AS16: 611.71 | AT16: 658.27 | AX16: 915.82 | AZ16: 658.2 | BA16: 684.78 | BB16: 866.02 | BC16: 876.08 | BD16: 884.36 | BE16: 885.03 | BF16: 981.69 | BG16: 982.03 | BH16: 713.58 | BI16: 597.33 | BL16: 658.27 | BM16: 666.44 | BN16: 956.14 | BO16: 945.65 | BP16: 951.87 | BQ16: 951.87 | BR16: 952.44 | BS16: 951.28 | BT16: 952.37 | BV16: 625.81 | BW16: 672.14 | BX16: 674.5 | BY16: 651.88 | BZ16: 632.75 | CC16: 632.75 | CD16: 633.2 | CE16: 613.66 | CF16: 676.74 | CG16: 519.37 | CH16: 604.68 | CI16: 704.93 | CJ16: 724.67 | CK16: 737.51 | CL16: 683.77 | CM16: 684.03 | CN16: 683.42 | CO16: 683.31 | CP16: 982.78 | CY16: 915.82 | CZ16: 649.28 | DA16: 650.85 | DC16: 695.34 | DD16: 662.92 | DE16: 664.36 | DF16: 664.35 | DG16: 664.36 | DH16: 709.47 | DI16: 709.28 | DJ16: 954.26 | DK16: 643.5 | DL16: 644.06 | DM16: 662 | DN16: 689.76 | DO16: 689.25 | DP16: 643.12 | DQ16: 643.13 | DS16: 657.22 | DT16: 658.97 | DU16: 735.34 | DV16: 794.55 | DW16: 794.45 | DX16: 735.3 | DY16: 915.82 | EC16: 742.13 | EW16: 1009.82 | EX16: 1009.82 | EY16: 1009.82 | EZ16: 1009.26 | FA16: 1009.26 | FB16: 984.43 | FE16: 984.45 | FF16: 983.57 | FG16: 1046.65 | FH16: 1046.64 | FI16: 965.06
A17: LIQ. DENISTY @ 15.6°C | B17: kg/m³ | C17: 947.36 | D17: 907.99 | E17: 911.73 | F17: 911.73 | G17: 911.73 | H17: 911.73 | I17: 911.73 | J17: 911.73 | K17: 911.73 | L17: 911.73 | M17: 911.73 | O17: 899.97 | P17: 883.77 | Q17: 899.43 | R17: 883.77 | S17: 883.77 | T17: 883.77 | U17: 883.77 | V17: 883.77 | Y17: 894.52 | Z17: 894.52 | AA17: 853 | AB17: 853 | AC17: 853 | AD17: 872.9 | AE17: 867.86 | AQ17: 853 | AR17: 856.95 | AS17: 857.13 | AT17: 870.43 | AX17: 998.86 | AZ17: 871.28 | BA17: 828.25 | BB17: 981.1 | BC17: 945.83 | BD17: 950.69 | BE17: 942.52 | BF17: 1000.81 | BG17: 1001.05 | BH17: 736.49 | BI17: 805.63 | BL17: 870.43 | BM17: 872.19 | BN17: 998.86 | BO17: 1014.39 | BP17: 1014.39 | BQ17: 1014.39 | BR17: 1014.39 | BS17: 1014.39 | BT17: 1014.39 | BV17: 804.67 | BW17: 868.14 | BX17: 871.56 | BY17: 872.76 | BZ17: 874.03 | CC17: 874.03 | CD17: 874.03 | CE17: 874.39 | CF17: 883.77 | CG17: 853 | CH17: 739.48 | CI17: 884.08 | CJ17: 800.81 | CK17: 796.95 | CL17: 708.19 | CM17: 708.19 | CN17: 708.19 | CO17: 708.19 | CP17: 1001.55 | CY17: 998.86 | CZ17: 883.77 | DA17: 883.77 | DC17: 802.31 | DD17: 728.41 | DE17: 728.41 | DF17: 728.41 | DG17: 728.41 | DH17: 728.41 | DI17: 728.41 | DJ17: 1014.39 | DK17: 815.42 | DL17: 815.42 | DM17: 815.42 | DN17: 815.42 | DO17: 815.42 | DP17: 815.42 | DQ17: 815.42 | DS17: 818.54 | DT17: 818.54 | DU17: 818.54 | DV17: 818.54 | DW17: 818.54 | DX17: 818.54 | DY17: 998.86 | EC17: 883.77 | EW17: 1028.62 | EX17: 1028.62 | EY17: 1028.62 | EZ17: 1028.62 | FA17: 1028.62 | FB17: 1014.21 | FE17: 1014.21 | FF17: 1014.25 | FG17: 1072.41 | FH17: 1072.39 | FI17: 997.34
A18: API LIQUID GRAVITY | C18: 17.72 | D18: 24.19 | E18: 23.55 | F18: 23.55 | G18: 23.55 | H18: 23.55 | I18: 23.55 | J18: 23.55 | K18: 23.55 | L18: 23.55 | M18: 23.55 | O18: 25.57 | P18: 28.45 | Q18: 25.67 | R18: 28.45 | S18: 28.45 | T18: 28.45 | U18: 28.45 | V18: 28.45 | Y18: 26.53 | Z18: 26.53 | AA18: 34.22 | AB18: 34.22 | AC18: 34.22 | AD18: 30.44 | AE18: 31.39 | AQ18: 34.22 | AR18: 33.46 | AS18: 33.42 | AT18: 30.9 | AX18: 10.02 | AZ18: 30.75 | BA18: 39.17 | BB18: 12.58 | BC18: 17.96 | BD18: 17.19 | BE18: 18.48 | BF18: 9.75 | BG18: 9.71 | BH18: 60.44 | BI18: 43.97 | BL18: 30.9 | BM18: 30.58 | BN18: 10.02 | BO18: 7.86 | BP18: 7.86 | BQ18: 7.86 | BR18: 7.86 | BS18: 7.86 | BT18: 7.86 | BV18: 44.18 | BW18: 31.33 | BX18: 30.69 | BY18: 30.47 | BZ18: 30.23 | CC18: 30.23 | CD18: 30.23 | CE18: 30.17 | CF18: 28.45 | CG18: 34.22 | CH18: 59.66 | CI18: 28.4 | CJ18: 45.02 | CK18: 45.88 | CL18: 68.11 | CM18: 68.11 | CN18: 68.11 | CO18: 68.11 | CP18: 9.64 | CY18: 10.02 | CZ18: 28.45 | DA18: 28.45 | DC18: 44.69 | DD18: 62.57 | DE18: 62.57 | DF18: 62.57 | DG18: 62.57 | DH18: 62.57 | DI18: 62.57 | DJ18: 7.86 | DK18: 41.86 | DL18: 41.86 | DM18: 41.86 | DN18: 41.86 | DO18: 41.86 | DP18: 41.86 | DQ18: 41.86 | DS18: 41.2 | DT18: 41.2 | DU18: 41.2 | DV18: 41.2 | DW18: 41.2 | DX18: 41.2 | DY18: 10.02 | EC18: 28.45 | EW18: 5.93 | EX18: 5.93 | EY18: 5.93 | EZ18: 5.93 | FA18: 5.93 | FB18: 7.88 | FE18: 7.88 | FF18: 7.87 | FG18: 0.32 | FH18: 0.32 | FI18: 10.24
A19: LIQ. VISC @ P&T | B19: cP | C19: 6.44 | D19: 3.55 | E19: 8.36 | F19: 3.75 | G19: 8.32 | H19: 4.26 | I19: 0.9 | J19: 0.9 | K19: 0.9 | L19: 0.88 | M19: 0.87 | O19: 0.79 | P19: 0.21 | Q19: 0.6 | R19: 1.54 | S19: 1.54 | T19: 2.38 | U19: 2.38 | V19: 1.54 | W19: 4.26 | X19: 4.26 | Y19: 0.11 | Z19: 0.08 | AA19: 0.05 | AB19: 0.05 | AC19: 0.05 | AD19: 0.06 | AE19: 0.06 | AQ19: 0.05 | AR19: 0.14 | AS19: 0.14 | AT19: 0.18 | AX19: 0.18 | AZ19: 0.17 | BA19: 0.32 | BB19: 0.29 | BC19: 1.34 | BD19: 0.96 | BE19: 1.62 | BF19: 0.63 | BG19: 0.63 | BH19: 0.47 | BI19: 0.15 | BL19: 0.18 | BM19: 0.18 | BN19: 0.27 | BO19: 0.27 | BP19: 0.29 | BQ19: 0.29 | BR19: 0.29 | BS19: 0.29 | BT19: 0.29 | BV19: 0.18 | BW19: 0.2 | BX19: 0.19 | BY19: 0.14 | BZ19: 0.11 | CC19: 0.11 | CD19: 0.11 | CE19: 0.09 | CF19: 0.17 | CG19: 0.05 | CH19: 0.16 | CI19: 0.53 | CJ19: 0.51 | CK19: 0.56 | CL19: 0.29 | CM19: 0.29 | CN19: 0.29 | CO19: 0.29 | CP19: 0.64 | CY19: 0.18 | CZ19: 0.12 | DA19: 0.12 | DC19: 0.39 | DD19: 0.26 | DE19: 0.26 | DF19: 0.26 | DG19: 0.26 | DH19: 0.42 | DI19: 0.42 | DJ19: 0.3 | DK19: 0.22 | DL19: 0.22 | DM19: 0.26 | DN19: 0.34 | DO19: 0.34 | DP19: 0.22 | DQ19: 0.22 | DS19: 0.25 | DT19: 0.25 | DU19: 0.59 | DV19: 1.75 | DW19: 1.75 | DX19: 0.59 | DY19: 0.18 | EC19: 0.46 | EW19: 1.32 | EX19: 1.32 | EY19: 1.32 | EZ19: 1.3 | FA19: 1.3 | FB19: 0.49 | FE19: 0.49 | FF19: 0.49 | FG19: 1.1 | FH19: 1.1 | FI19: 0.8
A20: SURFACE TENSION | B20: dyne/cm | C20: 26.89 | D20: 24.7 | E20: 26.85 | F20: 24.9 | G20: 26.84 | H20: 25.18 | I20: 20.81 | J20: 20.81 | K20: 20.81 | L20: 20.68 | M20: 20.65 | O20: 17.51 | P20: 13.42 | Q20: 16.43 | R20: 22.24 | S20: 22.24 | T20: 23.52 | U20: 23.52 | V20: 22.24 | Y20: 9.59 | Z20: 8.83 | AA20: 2.94 | AB20: 2.94 | AC20: 2.93 | AD20: 4.79 | AE20: 4.61 | AQ20: 2.94 | AR20: 7.16 | AS20: 7.18 | AT20: 10.26 | AX20: 48.26 | AZ20: 10.24 | BA20: 11.95 | BF20: 67.38 | BG20: 67.42 | BH20: 15.84 | BI20: 7.1 | BL20: 10.26 | BM20: 11.05 | BN20: 57.84 | BO20: 57.84 | BP20: 59.46 | BQ20: 59.46 | BR20: 59.34 | BS20: 59.27 | BT20: 59.33 | BV20: 8.99 | BW20: 12.37 | BX20: 12.25 | BY20: 10.62 | BZ20: 9.36 | CC20: 9.36 | CD20: 9.35 | CE20: 8.19 | CF20: 12.36 | CG20: 3.53 | CL20: 15.29 | CM20: 15.26 | CN20: 15.25 | CO20: 15.25 | CP20: 67.53 | CY20: 48.26 | CZ20: 10.54 | DA20: 10.51 | DD20: 15.26 | DE20: 15.21 | DF20: 15.21 | DG20: 15.21 | DJ20: 60 | DK20: 11.17 | DL20: 11.16 | DM20: 12.61 | DN20: 15 | DO20: 15 | DP20: 11.17 | DQ20: 11.17 | DS20: 12.3 | DT20: 12.26 | DU20: 19.23 | DX20: 19.23 | DY20: 48.26 | EC20: 17.51 | EW20: 57.7 | EX20: 57.7 | EY20: 57.7 | EZ20: 57.56 | FA20: 57.56 | FB20: 66.68 | FE20: 66.68 | FF20: 66.62 | FG20: 55.97 | FH20: 55.97
A21: LIQ. THERM. COND. | B21: W/(m.K) | C21: 0.12 | D21: 0.12 | E21: 0.12 | F21: 0.12 | G21: 0.12 | H21: 0.12 | I21: 0.11 | J21: 0.11 | K21: 0.11 | L21: 0.11 | M21: 0.11 | O21: 0.11 | P21: 0.1 | Q21: 0.1 | R21: 0.12 | S21: 0.12 | T21: 0.12 | U21: 0.12 | V21: 0.12 | Y21: 0.09 | Z21: 0.09 | AA21: 0.07 | AB21: 0.07 | AC21: 0.07 | AD21: 0.07 | AE21: 0.07 | AQ21: 0.07 | AR21: 0.07 | AS21: 0.07 | AT21: 0.08 | AX21: 0.69 | AZ21: 0.08 | BA21: 0.09 | BB21: 0.46 | BC21: 0.35 | BD21: 0.37 | BE21: 0.35 | BF21: 0.61 | BG21: 0.61 | BH21: 0.11 | BI21: 0.06 | BL21: 0.08 | BM21: 0.08 | BN21: 0.68 | BO21: 0.68 | BP21: 0.68 | BQ21: 0.68 | BR21: 0.68 | BS21: 0.68 | BT21: 0.68 | BV21: 0.08 | BW21: 0.1 | BX21: 0.1 | BY21: 0.09 | BZ21: 0.09 | CC21: 0.09 | CD21: 0.09 | CE21: 0.09 | CF21: 0.1 | CG21: 0.07 | CH21: 0.09 | CI21: 0.29 | CJ21: 0.15 | CK21: 0.15 | CL21: 0.11 | CM21: 0.11 | CN21: 0.11 | CO21: 0.11 | CP21: 0.61 | CY21: 0.69 | CZ21: 0.09 | DA21: 0.09 | DC21: 0.13 | DD21: 0.1 | DE21: 0.1 | DF21: 0.1 | DG21: 0.1 | DH21: 0.11 | DI21: 0.11 | DJ21: 0.68 | DK21: 0.1 | DL21: 0.1 | DM21: 0.1 | DN21: 0.1 | DO21: 0.1 | DP21: 0.1 | DQ21: 0.1 | DS21: 0.1 | DT21: 0.1 | DU21: 0.11 | DV21: 0.12 | DW21: 0.12 | DX21: 0.11 | DY21: 0.69 | EC21: 0.11 | EW21: 0.46 | EX21: 0.46 | EY21: 0.46 | EZ21: 0.46 | FA21: 0.46 | FB21: 0.65 | FE21: 0.65 | FF21: 0.65 | FG21: 0.47 | FH21: 0.47 | FI21: 0.42
A22: VAPOR PRESSURE | B22: MPa(a) | C22: 4.26e-07 | D22: 2.55e-06 | E22: 2.84e-07 | F22: 2.39e-06 | G22: 2.84e-07 | H22: 1.74e-06 | I22: 9.64e-05 | J22: 9.65e-05 | K22: 9.65e-05 | L22: 0 | M22: 0 | N22: 0 | O22: 23.92 | P22: 0.2 | Q22: 22.5 | R22: 0.15 | S22: 0.15 | T22: 0.13 | U22: 0.13 | V22: 0.15 | Y22: 14.66 | Z22: 13.73 | AA22: 11.04 | AB22: 11.04 | AC22: 11.02 | AD22: 12.09 | AE22: 14.29 | AF22: 0 | AG22: 0 | AH22: 0 | AI22: 0 | AJ22: 0 | AK22: 0 | AL22: 0 | AM22: 0 | AN22: 0 | AO22: 0 | AP22: 0 | AQ22: 11.04 | AR22: 15.69 | AS22: 15.69 | AT22: 15.75 | AU22: 5.96 | AV22: 1.74 | AW22: 1.55 | AX22: 0.5 | AY22: 0 | AZ22: 0 | BA22: 0 | BB22: 0 | BC22: 0 | BD22: 0 | BE22: 0 | BF22: 2.38 | BG22: 1.91 | BH22: 2.91 | BI22: 6.32 | BJ22: 0 | BK22: 0 | BL22: 3.09 | BM22: 3.09 | BN22: 0.12 | BO22: 0.12 | BP22: 0.09 | BQ22: 0.09 | BR22: 0.09 | BS22: 0.09 | BT22: 0.09 | BU22: 0 | BV22: 4.57 | BW22: 1.19 | BX22: 1.19 | BY22: 1.23 | BZ22: 1.25 | CA22: 13.04 | CB22: 13.08 | CC22: 0.3 | CD22: 0.3 | CE22: 0.34 | CF22: 0.2 | CG22: 11.88 | CH22: 11.55 | CI22: 11.85 | CJ22: 15.17 | CK22: 16.29 | CL22: 1.09 | CM22: 1.09 | CN22: 1.09 | CO22: 1.09 | CP22: 0.83 | CQ22: 74.92 | CR22: 76.38 | CS22: 4.61 | CT22: 4.51 | CU22: 5.96 | CV22: 4.69 | CW22: 1.52 | CX22: 1.52 | CY22: 0.5 | CZ22: 0.22 | DA22: 0.22 | DB22: 0.44 | DC22: 0.14 | DD22: 0.14 | DE22: 0.14 | DF22: 0.14 | DG22: 0.14 | DH22: 0.02 | DI22: 0.02 | DJ22: 0.08 | DK22: 0.19 | DL22: 0.19 | DM22: 0.16 | DN22: 0.12 | DO22: 0.12 | DP22: 0.19 | DQ22: 0.19 | DR22: 3.12 | DS22: 0.2 | DT22: 0.2 | DU22: 0.12 | DV22: 0.01 | DW22: 0.01 | DX22: 0.12 | DY22: 0.5 | DZ22: 1.53 | EA22: 0.74 | EB22: 0.59 | EC22: 0.18 | ED22: 2.36 | EE22: 2.36 | EF22: 1.53 | EG22: 4.61 | EH22: 0 | EI22: 0 | EJ22: 0 | EK22: 0 | EL22: 0 | EM22: 0 | EN22: 0 | EO22: 0 | EP22: 0 | EQ22: 0 | ER22: 0 | ES22: 0 | ET22: 0 | EU22: 0 | EV22: 0 | EW22: 0.01 | EX22: 0.01 | EY22: 0.01 | EZ22: 0.02 | FA22: 0.02 | FB22: 0 | FC22: 0 | FD22: 0 | FE22: 2.29 | FF22: 2.27 | FG22: 2.89 | FH22: 2.89 | FI22: 2.29
A23: VAP. FLOW @ 0°C | B23: Nm³/hr | N23: 4924.39 | O23: 1809.15 | Q23: 1637.83 | AF23: 3124.23 | AG23: 6681.49 | AH23: 8127.78 | AI23: 7371.57 | AJ23: 5294.93 | AK23: 22.48 | AL23: 22.48 | AM23: 22.48 | AN23: 22.44 | AO23: 22.44 | AP23: 112.35 | AR23: 1587.11 | AS23: 1665.59 | AT23: 10904.22 | AU23: 8339.43 | AV23: 6488.82 | AW23: 6517.34 | AY23: 10904.22 | AZ23: 11015.9 | BA23: 10888.31 | BB23: 10986.93 | BC23: 9483.93 | BD23: 19539.95 | BE23: 19312.42 | BF23: 0.79 | BG23: 0.78 | BH23: 35.81 | BI23: 896.8 | BJ23: 19312.42 | BK23: 19312.42 | BM23: 1620.78 | BU23: 9850.47 | BV23: 358.69 | BX23: 971.48 | BY23: 1314.39 | BZ23: 1735.26 | CA23: 1735.26 | CB23: 1735.26 | CE23: 97.24 | CH23: 9483.27 | CI23: 9410.11 | CJ23: 2876.67 | CK23: 2531.09 | CQ23: 2531.09 | CR23: 2531.09 | CS23: 3670.33 | CT23: 3670.33 | CU23: 33357.7 | CV23: 33831.21 | CW23: 8339.43 | CX23: 25018.28 | DB23: 23189.1 | DR23: 1023.29 | DZ23: 4152.41 | EA23: 6488.82 | EB23: 6488.82 | ED23: 584.76 | EE23: 10886.56 | EF23: 29205.29 | EG23: 4953.99 | EH23: 35524.42 | EI23: 44656.69 | EJ23: 44656.69 | EK23: 44656.69 | EL23: 44656.69 | EM23: 44656.69 | EN23: 44656.69 | EO23: 44656.69 | EP23: 44656.69 | EQ23: 44656.69 | ER23: 35524.39 | ES23: 9132.26 | ET23: 9132.26 | EU23: 9132.26 | EV23: 4924.39 | FB23: 15620.35 | FC23: 15620.35 | FD23: 15620.35 | FF23: 8.53e-05 | FH23: 38.87 | FI23: 187.52
A24: VAP. DENSITY @ 0°C | B24: kg/m³ | N24: 0.09 | O24: 0.09 | Q24: 0.09 | AF24: 0.09 | AG24: 0.09 | AH24: 0.09 | AI24: 0.09 | AJ24: 0.09 | AK24: 0.74 | AL24: 0.85 | AM24: 0.85 | AN24: 1.11 | AO24: 1.2 | AP24: 0.97 | AR24: 0.72 | AS24: 0.73 | AT24: 1.15 | AU24: 0.8 | AV24: 0.8 | AW24: 0.8 | AY24: 1.15 | AZ24: 1.15 | BA24: 1.06 | BB24: 0.95 | BC24: 0.79 | BD24: 0.63 | BE24: 0.61 | BF24: 0.83 | BG24: 0.86 | BH24: 1.04 | BI24: 3.6 | BJ24: 0.61 | BK24: 0.61 | BM24: 1.7 | BU24: 0.44 | BV24: 2.79 | BX24: 2.19 | BY24: 3.25 | BZ24: 4.49 | CA24: 4.49 | CB24: 4.49 | CE24: 5.96 | CH24: 2.18 | CI24: 1.93 | CJ24: 1.33 | CK24: 1.24 | CQ24: 1.24 | CR24: 1.24 | CS24: 0.8 | CT24: 0.8 | CU24: 0.8 | CV24: 0.8 | CW24: 0.8 | CX24: 0.8 | DB24: 2.8 | DR24: 3.85 | DZ24: 0.8 | EA24: 0.8 | EB24: 0.8 | ED24: 0.8 | EE24: 0.8 | EF24: 0.8 | EG24: 0.8 | EH24: 0.09 | EI24: 0.09 | EJ24: 0.09 | EK24: 0.09 | EL24: 0.09 | EM24: 0.09 | EN24: 0.09 | EO24: 0.09 | EP24: 0.09 | EQ24: 0.09 | ER24: 0.09 | ES24: 0.09 | ET24: 0.09 | EU24: 0.09 | EV24: 0.09 | FB24: 0.39 | FC24: 0.39 | FD24: 0.39 | FF24: 0.11 | FH24: 0.38 | FI24: 1.21
A25: VAP. VISC @ P&T | B25: cP | N25: 0.01 | O25: 0.01 | Q25: 0.01 | AF25: 0.01 | AG25: 0.01 | AH25: 0.01 | AI25: 0.01 | AJ25: 0.01 | AK25: 0.02 | AL25: 0.03 | AM25: 0.03 | AN25: 0.03 | AO25: 0.03 | AP25: 0.03 | AR25: 0.02 | AS25: 0.02 | AT25: 0.02 | AU25: 0.019 | AV25: 0.02 | AW25: 0.02 | AY25: 0.02 | AZ25: 0.02 | BA25: 0.02 | BB25: 0.02 | BC25: 0.01 | BD25: 0.01 | BE25: 0.01 | BF25: 0.01 | BG25: 0.01 | BH25: 0.01 | BI25: 0.01 | BJ25: 0.01 | BK25: 0.01 | BM25: 0.02 | BU25: 0.01 | BV25: 0.02 | BX25: 0.02 | BY25: 0.02 | BZ25: 0.01 | CA25: 0.01 | CB25: 0.01 | CE25: 0.01 | CH25: 0.01 | CI25: 0.01 | CJ25: 0.01 | CK25: 0.01 | CQ25: 0.01 | CR25: 0.01 | CS25: 0.02 | CT25: 0.02 | CU25: 0.02 | CV25: 0.02 | CW25: 0.02 | CX25: 0.02 | DB25: 0.01 | DR25: 0.01 | DZ25: 0.02 | EA25: 0.01 | EB25: 0.01 | ED25: 0.02 | EE25: 0.02 | EF25: 0.02 | EG25: 0.02 | EH25: 0.01 | EI25: 0.01 | EJ25: 0.01 | EK25: 0.01 | EL25: 0.01 | EM25: 0.01 | EN25: 0.01 | EO25: 0.01 | EP25: 0.01 | EQ25: 0.01 | ER25: 0.01 | ES25: 0.01 | ET25: 0.01 | EU25: 0.01 | EV25: 0.01 | FB25: 0.01 | FC25: 0.01 | FD25: 0.01 | FF25: 0.01 | FH25: 0.01 | FI25: 0.01
A26: VAP. THERM COND | B26: W/(m.K) | N26: 0.22 | O26: 0.25 | Q26: 0.25 | AF26: 0.22 | AG26: 0.22 | AH26: 0.22 | AI26: 0.22 | AJ26: 0.22 | AK26: 0.18 | AL26: 0.17 | AM26: 0.17 | AN26: 0.15 | AO26: 0.15 | AP26: 0.16 | AR26: 0.14 | AS26: 0.14 | AT26: 0.09 | AU26: 0.042 | AV26: 0.03 | AW26: 0.03 | AY26: 0.09 | AZ26: 0.1 | BA26: 0.08 | BB26: 0.07 | BC26: 0.07 | BD26: 0.09 | BE26: 0.09 | BF26: 0.06 | BG26: 0.06 | BH26: 0.05 | BI26: 0.04 | BJ26: 0.09 | BK26: 0.09 | BM26: 0.07 | BU26: 0.11 | BV26: 0.04 | BX26: 0.04 | BY26: 0.04 | BZ26: 0.04 | CA26: 0.04 | CB26: 0.04 | CE26: 0.04 | CH26: 0.03 | CI26: 0.03 | CJ26: 0.04 | CK26: 0.04 | CQ26: 0.04 | CR26: 0.04 | CS26: 0.04 | CT26: 0.04 | CU26: 0.04 | CV26: 0.04 | CW26: 0.03 | CX26: 0.03 | DB26: 0.02 | DR26: 0.03 | DZ26: 0.03 | EA26: 0.03 | EB26: 0.03 | ED26: 0.04 | EE26: 0.04 | EF26: 0.03 | EG26: 0.04 | EH26: 0.18 | EI26: 0.18 | EJ26: 0.18 | EK26: 0.21 | EL26: 0.18 | EM26: 0.18 | EN26: 0.21 | EO26: 0.19 | EP26: 0.19 | EQ26: 0.22 | ER26: 0.22 | ES26: 0.22 | ET26: 0.19 | EU26: 0.18 | EV26: 0.22 | FB26: 0.12 | FC26: 0.12 | FD26: 0.12 | FF26: 0.18 | FH26: 0.11 | FI26: 0.04
A27: VAPOR MW | B27: g/mol | N27: 2.03 | O27: 2.03 | Q27: 2.03 | AF27: 2.03 | AG27: 2.03 | AH27: 2.03 | AI27: 2.03 | AJ27: 2.03 | AK27: 16.61 | AL27: 19.1 | AM27: 19.1 | AN27: 24.82 | AO27: 26.89 | AP27: 21.83 | AR27: 16.21 | AS27: 16.27 | AT27: 25.88 | AU27: 18.02 | AV27: 18.02 | AW27: 18.02 | AY27: 25.88 | AZ27: 25.82 | BA27: 23.69 | BB27: 21.32 | BC27: 17.77 | BD27: 14.14 | BE27: 13.7 | BF27: 18.57 | BG27: 19.19 | BH27: 23.27 | BI27: 80.66 | BJ27: 13.7 | BK27: 13.7 | BM27: 38.12 | BU27: 9.83 | BV27: 62.63 | BX27: 49.09 | BY27: 72.85 | BZ27: 100.74 | CA27: 100.74 | CB27: 100.74 | CE27: 133.58 | CH27: 48.86 | CI27: 43.29 | CJ27: 29.78 | CK27: 27.72 | CQ27: 27.72 | CR27: 27.72 | CS27: 18.02 | CT27: 18.02 | CU27: 18.02 | CV27: 18.02 | CW27: 18.02 | CX27: 18.02 | DB27: 62.65 | DR27: 86.33 | DZ27: 18.02 | EA27: 18.02 | EB27: 18.02 | ED27: 18.02 | EE27: 18.02 | EF27: 18.02 | EG27: 18.02 | EH27: 2.03 | EI27: 2.03 | EJ27: 2.03 | EK27: 2.03 | EL27: 2.03 | EM27: 2.03 | EN27: 2.03 | EO27: 2.03 | EP27: 2.03 | EQ27: 2.03 | ER27: 2.03 | ES27: 2.03 | ET27: 2.03 | EU27: 2.03 | EV27: 2.03 | FB27: 8.71 | FC27: 8.71 | FD27: 8.71 | FF27: 2.36 | FH27: 8.59 | FI27: 27.01
